ERROR django.request 2017-10-24 18:07:01 C:\Python27\lib\site-packages\django\core\handlers\base.py base:handle_uncaught_exception 284 Internal Server Error: /user/delete/3
Traceback (most recent call last):
  File "C:\Python27\lib\site-packages\django\core\handlers\base.py", line 149, in get_response
    response = self.process_exception_by_middleware(e, request)
  File "C:\Python27\lib\site-packages\django\core\handlers\base.py", line 147, in get_response
    response = wrapped_callback(request, *callback_args, **callback_kwargs)
  File "E:\share\UserCenter\UsersControl\views\user.py", line 95, in user_delete
    status, res = executingldap.delete_ldap_user(user_obj)
  File "E:\share\UserCenter\UsersControl\views\executing_ldap.py", line 89, in delete_ldap_user
    status, res = self.ldaptools.delete_user(dn)
  File "E:\share\UserCenter\UsersControl\LDAP\LADPtool.py", line 102, in delete_user
    raise APIException(error_message)
APIException: {'info': 'invalid DN', 'errno': 2, 'desc': 'Invalid DN syntax'}
ERROR django.request 2017-10-24 18:09:02 C:\Python27\lib\site-packages\django\core\handlers\base.py base:handle_uncaught_exception 284 Internal Server Error: /user/delete/3
Traceback (most recent call last):
  File "C:\Python27\lib\site-packages\django\core\handlers\base.py", line 149, in get_response
    response = self.process_exception_by_middleware(e, request)
  File "C:\Python27\lib\site-packages\django\core\handlers\base.py", line 147, in get_response
    response = wrapped_callback(request, *callback_args, **callback_kwargs)
  File "E:\share\UserCenter\UsersControl\views\user.py", line 95, in user_delete
    status, res = executingldap.delete_ldap_user(user_obj)
  File "E:\share\UserCenter\UsersControl\views\executing_ldap.py", line 89, in delete_ldap_user
    status, res = self.ldaptools.delete_user(dn)
  File "E:\share\UserCenter\UsersControl\LDAP\LADPtool.py", line 102, in delete_user
    raise APIException(error_message)
APIException: {'matched': 'ou=People,dc=ldap,dc=gomeo2o,dc=cn', 'desc': 'No such object'}
ERROR django.request 2017-10-24 18:10:35 C:\Python27\lib\site-packages\django\core\handlers\base.py base:handle_uncaught_exception 284 Internal Server Error: /permission/edit/9/
Traceback (most recent call last):
  File "C:\Python27\lib\site-packages\django\core\handlers\base.py", line 149, in get_response
    response = self.process_exception_by_middleware(e, request)
  File "C:\Python27\lib\site-packages\django\core\handlers\base.py", line 147, in get_response
    response = wrapped_callback(request, *callback_args, **callback_kwargs)
  File "C:\Python27\lib\site-packages\django\contrib\auth\decorators.py", line 23, in _wrapped_view
    return view_func(request, *args, **kwargs)
  File "E:\share\UserCenter\UsersControl\views\permission.py", line 53, in permission_edit
    form = forms.PermissionEditForm(instance=permission)
  File "E:\share\UserCenter\UsersControl\forms.py", line 192, in __init__
    super(PermissionEditForm, self).__init__(*args, **kwargs)
  File "E:\share\UserCenter\UsersControl\forms.py", line 166, in __init__
    super(AddPermissionForm, self).__init__(*args,**kwargs)
  File "C:\Python27\lib\site-packages\django\forms\models.py", line 282, in __init__
    object_data = model_to_dict(instance, opts.fields, opts.exclude)
  File "C:\Python27\lib\site-packages\django\forms\models.py", line 84, in model_to_dict
    opts = instance._meta
AttributeError: 'QuerySet' object has no attribute '_meta'
ERROR django.request 2017-10-24 18:10:49 C:\Python27\lib\site-packages\django\core\handlers\base.py base:handle_uncaught_exception 284 Internal Server Error: /permission/edit/10/
Traceback (most recent call last):
  File "C:\Python27\lib\site-packages\django\core\handlers\base.py", line 149, in get_response
    response = self.process_exception_by_middleware(e, request)
  File "C:\Python27\lib\site-packages\django\core\handlers\base.py", line 147, in get_response
    response = wrapped_callback(request, *callback_args, **callback_kwargs)
  File "C:\Python27\lib\site-packages\django\contrib\auth\decorators.py", line 23, in _wrapped_view
    return view_func(request, *args, **kwargs)
  File "E:\share\UserCenter\UsersControl\views\permission.py", line 53, in permission_edit
    form = forms.PermissionEditForm(instance=permission)
  File "E:\share\UserCenter\UsersControl\forms.py", line 192, in __init__
    super(PermissionEditForm, self).__init__(*args, **kwargs)
  File "E:\share\UserCenter\UsersControl\forms.py", line 166, in __init__
    super(AddPermissionForm, self).__init__(*args,**kwargs)
  File "C:\Python27\lib\site-packages\django\forms\models.py", line 282, in __init__
    object_data = model_to_dict(instance, opts.fields, opts.exclude)
  File "C:\Python27\lib\site-packages\django\forms\models.py", line 84, in model_to_dict
    opts = instance._meta
AttributeError: 'QuerySet' object has no attribute '_meta'
ERROR django.request 2017-10-24 18:11:46 C:\Python27\lib\site-packages\django\core\handlers\base.py base:handle_uncaught_exception 284 Internal Server Error: /permission/edit/9/
Traceback (most recent call last):
  File "C:\Python27\lib\site-packages\django\core\handlers\base.py", line 149, in get_response
    response = self.process_exception_by_middleware(e, request)
  File "C:\Python27\lib\site-packages\django\core\handlers\base.py", line 147, in get_response
    response = wrapped_callback(request, *callback_args, **callback_kwargs)
  File "C:\Python27\lib\site-packages\django\contrib\auth\decorators.py", line 23, in _wrapped_view
    return view_func(request, *args, **kwargs)
  File "E:\share\UserCenter\UsersControl\views\permission.py", line 53, in permission_edit
    form = forms.PermissionEditForm(instance=permission)
  File "E:\share\UserCenter\UsersControl\forms.py", line 192, in __init__
    super(PermissionEditForm, self).__init__(*args, **kwargs)
  File "E:\share\UserCenter\UsersControl\forms.py", line 166, in __init__
    super(AddPermissionForm, self).__init__(*args,**kwargs)
  File "C:\Python27\lib\site-packages\django\forms\models.py", line 282, in __init__
    object_data = model_to_dict(instance, opts.fields, opts.exclude)
  File "C:\Python27\lib\site-packages\django\forms\models.py", line 84, in model_to_dict
    opts = instance._meta
AttributeError: 'QuerySet' object has no attribute '_meta'
ERROR django.request 2017-10-24 18:15:52 C:\Python27\lib\site-packages\django\core\handlers\base.py base:handle_uncaught_exception 284 Internal Server Error: /permission/edit/10/
Traceback (most recent call last):
  File "C:\Python27\lib\site-packages\django\core\handlers\base.py", line 149, in get_response
    response = self.process_exception_by_middleware(e, request)
  File "C:\Python27\lib\site-packages\django\core\handlers\base.py", line 147, in get_response
    response = wrapped_callback(request, *callback_args, **callback_kwargs)
  File "C:\Python27\lib\site-packages\django\contrib\auth\decorators.py", line 23, in _wrapped_view
    return view_func(request, *args, **kwargs)
  File "E:\share\UserCenter\UsersControl\views\permission.py", line 53, in permission_edit
    form = forms.PermissionEditForm(instance=permission)
  File "E:\share\UserCenter\UsersControl\forms.py", line 192, in __init__
    super(PermissionEditForm, self).__init__(*args, **kwargs)
  File "C:\Python27\lib\site-packages\django\forms\models.py", line 282, in __init__
    object_data = model_to_dict(instance, opts.fields, opts.exclude)
  File "C:\Python27\lib\site-packages\django\forms\models.py", line 84, in model_to_dict
    opts = instance._meta
AttributeError: 'QuerySet' object has no attribute '_meta'
ERROR django.request 2017-10-24 18:18:20 C:\Python27\lib\site-packages\django\core\handlers\base.py base:handle_uncaught_exception 284 Internal Server Error: /permission/edit/9/
Traceback (most recent call last):
  File "C:\Python27\lib\site-packages\django\core\handlers\base.py", line 149, in get_response
    response = self.process_exception_by_middleware(e, request)
  File "C:\Python27\lib\site-packages\django\core\handlers\base.py", line 147, in get_response
    response = wrapped_callback(request, *callback_args, **callback_kwargs)
  File "C:\Python27\lib\site-packages\django\contrib\auth\decorators.py", line 23, in _wrapped_view
    return view_func(request, *args, **kwargs)
  File "E:\share\UserCenter\UsersControl\views\permission.py", line 53, in permission_edit
    form = forms.PermissionEditForm(instance=permission)
  File "E:\share\UserCenter\UsersControl\forms.py", line 192, in __init__
    super(PermissionEditForm, self).__init__(*args, **kwargs)
  File "C:\Python27\lib\site-packages\django\forms\models.py", line 282, in __init__
    object_data = model_to_dict(instance, opts.fields, opts.exclude)
  File "C:\Python27\lib\site-packages\django\forms\models.py", line 84, in model_to_dict
    opts = instance._meta
AttributeError: 'QuerySet' object has no attribute '_meta'
ERROR django.request 2017-10-24 18:20:04 C:\Python27\lib\site-packages\django\core\handlers\base.py base:handle_uncaught_exception 284 Internal Server Error: /permission/edit/9/
Traceback (most recent call last):
  File "C:\Python27\lib\site-packages\django\core\handlers\base.py", line 149, in get_response
    response = self.process_exception_by_middleware(e, request)
  File "C:\Python27\lib\site-packages\django\core\handlers\base.py", line 147, in get_response
    response = wrapped_callback(request, *callback_args, **callback_kwargs)
  File "C:\Python27\lib\site-packages\django\contrib\auth\decorators.py", line 23, in _wrapped_view
    return view_func(request, *args, **kwargs)
  File "E:\share\UserCenter\UsersControl\views\permission.py", line 53, in permission_edit
    form = forms.PermissionEditForm(instance=permission)
  File "E:\share\UserCenter\UsersControl\forms.py", line 192, in __init__
    super(PermissionEditForm, self).__init__(*args, **kwargs)
  File "C:\Python27\lib\site-packages\django\forms\models.py", line 282, in __init__
    object_data = model_to_dict(instance, opts.fields, opts.exclude)
  File "C:\Python27\lib\site-packages\django\forms\models.py", line 84, in model_to_dict
    opts = instance._meta
AttributeError: 'QuerySet' object has no attribute '_meta'
ERROR django.request 2017-10-24 18:21:09 C:\Python27\lib\site-packages\django\core\handlers\base.py base:handle_uncaught_exception 284 Internal Server Error: /permission/edit/9/
Traceback (most recent call last):
  File "C:\Python27\lib\site-packages\django\core\handlers\base.py", line 149, in get_response
    response = self.process_exception_by_middleware(e, request)
  File "C:\Python27\lib\site-packages\django\core\handlers\base.py", line 147, in get_response
    response = wrapped_callback(request, *callback_args, **callback_kwargs)
  File "C:\Python27\lib\site-packages\django\contrib\auth\decorators.py", line 23, in _wrapped_view
    return view_func(request, *args, **kwargs)
  File "E:\share\UserCenter\UsersControl\views\permission.py", line 53, in permission_edit
    form = forms.PermissionEditForm(instance=permission)
  File "E:\share\UserCenter\UsersControl\forms.py", line 192, in __init__
    super(PermissionEditForm, self).__init__(*args, **kwargs)
  File "C:\Python27\lib\site-packages\django\forms\models.py", line 282, in __init__
    object_data = model_to_dict(instance, opts.fields, opts.exclude)
  File "C:\Python27\lib\site-packages\django\forms\models.py", line 84, in model_to_dict
    opts = instance._meta
AttributeError: 'QuerySet' object has no attribute '_meta'
ERROR django.request 2017-10-24 18:23:39 C:\Python27\lib\site-packages\django\core\handlers\base.py base:handle_uncaught_exception 284 Internal Server Error: /permission/edit/9/
Traceback (most recent call last):
  File "C:\Python27\lib\site-packages\django\core\handlers\base.py", line 149, in get_response
    response = self.process_exception_by_middleware(e, request)
  File "C:\Python27\lib\site-packages\django\core\handlers\base.py", line 147, in get_response
    response = wrapped_callback(request, *callback_args, **callback_kwargs)
  File "C:\Python27\lib\site-packages\django\contrib\auth\decorators.py", line 23, in _wrapped_view
    return view_func(request, *args, **kwargs)
  File "E:\share\UserCenter\UsersControl\views\permission.py", line 53, in permission_edit
    form = forms.PermissionEditForm(instance=permission)
  File "E:\share\UserCenter\UsersControl\forms.py", line 192, in __init__
    super(PermissionEditForm, self).__init__(*args, **kwargs)
  File "C:\Python27\lib\site-packages\django\forms\models.py", line 282, in __init__
    object_data = model_to_dict(instance, opts.fields, opts.exclude)
  File "C:\Python27\lib\site-packages\django\forms\models.py", line 84, in model_to_dict
    opts = instance._meta
AttributeError: 'QuerySet' object has no attribute '_meta'
ERROR django.request 2017-10-24 18:23:58 C:\Python27\lib\site-packages\django\core\handlers\base.py base:handle_uncaught_exception 284 Internal Server Error: /permission/edit/9/
Traceback (most recent call last):
  File "C:\Python27\lib\site-packages\django\core\handlers\base.py", line 149, in get_response
    response = self.process_exception_by_middleware(e, request)
  File "C:\Python27\lib\site-packages\django\core\handlers\base.py", line 147, in get_response
    response = wrapped_callback(request, *callback_args, **callback_kwargs)
  File "C:\Python27\lib\site-packages\django\contrib\auth\decorators.py", line 23, in _wrapped_view
    return view_func(request, *args, **kwargs)
  File "E:\share\UserCenter\UsersControl\views\permission.py", line 53, in permission_edit
    form = forms.PermissionEditForm(instance=permission)
  File "E:\share\UserCenter\UsersControl\forms.py", line 192, in __init__
    super(PermissionEditForm, self).__init__(*args, **kwargs)
  File "C:\Python27\lib\site-packages\django\forms\models.py", line 282, in __init__
    object_data = model_to_dict(instance, opts.fields, opts.exclude)
  File "C:\Python27\lib\site-packages\django\forms\models.py", line 84, in model_to_dict
    opts = instance._meta
AttributeError: 'QuerySet' object has no attribute '_meta'
ERROR django.request 2017-10-24 18:24:45 C:\Python27\lib\site-packages\django\core\handlers\base.py base:handle_uncaught_exception 284 Internal Server Error: /permission/edit/9/
Traceback (most recent call last):
  File "C:\Python27\lib\site-packages\django\core\handlers\base.py", line 149, in get_response
    response = self.process_exception_by_middleware(e, request)
  File "C:\Python27\lib\site-packages\django\core\handlers\base.py", line 147, in get_response
    response = wrapped_callback(request, *callback_args, **callback_kwargs)
  File "C:\Python27\lib\site-packages\django\contrib\auth\decorators.py", line 23, in _wrapped_view
    return view_func(request, *args, **kwargs)
  File "E:\share\UserCenter\UsersControl\views\permission.py", line 53, in permission_edit
    form = forms.PermissionEditForm(instance=permission)
  File "E:\share\UserCenter\UsersControl\forms.py", line 192, in __init__
    super(PermissionEditForm, self).__init__(*args, **kwargs)
  File "C:\Python27\lib\site-packages\django\forms\models.py", line 282, in __init__
    object_data = model_to_dict(instance, opts.fields, opts.exclude)
  File "C:\Python27\lib\site-packages\django\forms\models.py", line 84, in model_to_dict
    opts = instance._meta
AttributeError: 'QuerySet' object has no attribute '_meta'
ERROR django.request 2017-10-24 18:24:49 C:\Python27\lib\site-packages\django\core\handlers\base.py base:handle_uncaught_exception 284 Internal Server Error: /permission/edit/9/
Traceback (most recent call last):
  File "C:\Python27\lib\site-packages\django\core\handlers\base.py", line 149, in get_response
    response = self.process_exception_by_middleware(e, request)
  File "C:\Python27\lib\site-packages\django\core\handlers\base.py", line 147, in get_response
    response = wrapped_callback(request, *callback_args, **callback_kwargs)
  File "C:\Python27\lib\site-packages\django\contrib\auth\decorators.py", line 23, in _wrapped_view
    return view_func(request, *args, **kwargs)
  File "E:\share\UserCenter\UsersControl\views\permission.py", line 53, in permission_edit
    form = forms.PermissionEditForm(instance=permission)
  File "E:\share\UserCenter\UsersControl\forms.py", line 192, in __init__
    super(PermissionEditForm, self).__init__(*args, **kwargs)
  File "C:\Python27\lib\site-packages\django\forms\models.py", line 282, in __init__
    object_data = model_to_dict(instance, opts.fields, opts.exclude)
  File "C:\Python27\lib\site-packages\django\forms\models.py", line 84, in model_to_dict
    opts = instance._meta
AttributeError: 'QuerySet' object has no attribute '_meta'
ERROR django.request 2017-10-24 18:27:40 C:\Python27\lib\site-packages\django\core\handlers\base.py base:handle_uncaught_exception 284 Internal Server Error: /permission/edit/9/
Traceback (most recent call last):
  File "C:\Python27\lib\site-packages\django\core\handlers\base.py", line 149, in get_response
    response = self.process_exception_by_middleware(e, request)
  File "C:\Python27\lib\site-packages\django\core\handlers\base.py", line 147, in get_response
    response = wrapped_callback(request, *callback_args, **callback_kwargs)
  File "C:\Python27\lib\site-packages\django\contrib\auth\decorators.py", line 23, in _wrapped_view
    return view_func(request, *args, **kwargs)
  File "E:\share\UserCenter\UsersControl\views\permission.py", line 53, in permission_edit
    form = forms.PermissionEditForm(instance=permission)
  File "E:\share\UserCenter\UsersControl\forms.py", line 192, in __init__
    super(PermissionEditForm, self).__init__(*args, **kwargs)
  File "C:\Python27\lib\site-packages\django\forms\models.py", line 282, in __init__
    object_data = model_to_dict(instance, opts.fields, opts.exclude)
  File "C:\Python27\lib\site-packages\django\forms\models.py", line 84, in model_to_dict
    opts = instance._meta
AttributeError: 'QuerySet' object has no attribute '_meta'
ERROR django.request 2017-10-24 18:27:49 C:\Python27\lib\site-packages\django\core\handlers\base.py base:handle_uncaught_exception 284 Internal Server Error: /permission/edit/9/
Traceback (most recent call last):
  File "C:\Python27\lib\site-packages\django\core\handlers\base.py", line 149, in get_response
    response = self.process_exception_by_middleware(e, request)
  File "C:\Python27\lib\site-packages\django\core\handlers\base.py", line 147, in get_response
    response = wrapped_callback(request, *callback_args, **callback_kwargs)
  File "C:\Python27\lib\site-packages\django\contrib\auth\decorators.py", line 23, in _wrapped_view
    return view_func(request, *args, **kwargs)
  File "E:\share\UserCenter\UsersControl\views\permission.py", line 53, in permission_edit
    form = forms.PermissionEditForm(instance=permission)
  File "E:\share\UserCenter\UsersControl\forms.py", line 192, in __init__
    super(PermissionEditForm, self).__init__(*args, **kwargs)
  File "C:\Python27\lib\site-packages\django\forms\models.py", line 282, in __init__
    object_data = model_to_dict(instance, opts.fields, opts.exclude)
  File "C:\Python27\lib\site-packages\django\forms\models.py", line 84, in model_to_dict
    opts = instance._meta
AttributeError: 'QuerySet' object has no attribute '_meta'
ERROR django.request 2017-10-24 18:29:26 C:\Python27\lib\site-packages\django\core\handlers\base.py base:handle_uncaught_exception 284 Internal Server Error: /permission/edit/10/
Traceback (most recent call last):
  File "C:\Python27\lib\site-packages\django\core\handlers\base.py", line 149, in get_response
    response = self.process_exception_by_middleware(e, request)
  File "C:\Python27\lib\site-packages\django\core\handlers\base.py", line 147, in get_response
    response = wrapped_callback(request, *callback_args, **callback_kwargs)
  File "C:\Python27\lib\site-packages\django\contrib\auth\decorators.py", line 23, in _wrapped_view
    return view_func(request, *args, **kwargs)
  File "E:\share\UserCenter\UsersControl\views\permission.py", line 53, in permission_edit
    form = forms.PermissionEditForm(instance=permission)
  File "E:\share\UserCenter\UsersControl\forms.py", line 192, in __init__
    super(PermissionEditForm, self).__init__(*args, **kwargs)
  File "C:\Python27\lib\site-packages\django\forms\models.py", line 282, in __init__
    object_data = model_to_dict(instance, opts.fields, opts.exclude)
  File "C:\Python27\lib\site-packages\django\forms\models.py", line 84, in model_to_dict
    opts = instance._meta
AttributeError: 'QuerySet' object has no attribute '_meta'
ERROR django.request 2017-10-24 18:32:02 C:\Python27\lib\site-packages\django\core\handlers\base.py base:handle_uncaught_exception 284 Internal Server Error: /permission/edit/10/
Traceback (most recent call last):
  File "C:\Python27\lib\site-packages\django\core\handlers\base.py", line 149, in get_response
    response = self.process_exception_by_middleware(e, request)
  File "C:\Python27\lib\site-packages\django\core\handlers\base.py", line 147, in get_response
    response = wrapped_callback(request, *callback_args, **callback_kwargs)
  File "C:\Python27\lib\site-packages\django\contrib\auth\decorators.py", line 23, in _wrapped_view
    return view_func(request, *args, **kwargs)
  File "E:\share\UserCenter\UsersControl\views\permission.py", line 53, in permission_edit
    form = forms.PermissionEditForm(instance=permission)
  File "E:\share\UserCenter\UsersControl\forms.py", line 192, in __init__
    super(PermissionEditForm, self).__init__(*args, **kwargs)
  File "C:\Python27\lib\site-packages\django\forms\models.py", line 282, in __init__
    object_data = model_to_dict(instance, opts.fields, opts.exclude)
  File "C:\Python27\lib\site-packages\django\forms\models.py", line 84, in model_to_dict
    opts = instance._meta
AttributeError: 'QuerySet' object has no attribute '_meta'
ERROR django.request 2017-10-24 18:36:40 C:\Python27\lib\site-packages\django\core\handlers\base.py base:handle_uncaught_exception 284 Internal Server Error: /permission/edit/9/
Traceback (most recent call last):
  File "C:\Python27\lib\site-packages\django\core\handlers\base.py", line 149, in get_response
    response = self.process_exception_by_middleware(e, request)
  File "C:\Python27\lib\site-packages\django\core\handlers\base.py", line 147, in get_response
    response = wrapped_callback(request, *callback_args, **callback_kwargs)
  File "C:\Python27\lib\site-packages\django\contrib\auth\decorators.py", line 23, in _wrapped_view
    return view_func(request, *args, **kwargs)
  File "E:\share\UserCenter\UsersControl\views\permission.py", line 53, in permission_edit
    form = forms.PermissionEditForm(instance=permission)
  File "E:\share\UserCenter\UsersControl\forms.py", line 192, in __init__
    super(PermissionEditForm, self).__init__(*args, **kwargs)
  File "C:\Python27\lib\site-packages\django\forms\models.py", line 282, in __init__
    object_data = model_to_dict(instance, opts.fields, opts.exclude)
  File "C:\Python27\lib\site-packages\django\forms\models.py", line 84, in model_to_dict
    opts = instance._meta
AttributeError: 'QuerySet' object has no attribute '_meta'
ERROR django.request 2017-10-24 18:43:14 C:\Python27\lib\site-packages\django\core\handlers\base.py base:handle_uncaught_exception 284 Internal Server Error: /permission/edit/9/
Traceback (most recent call last):
  File "C:\Python27\lib\site-packages\django\core\handlers\base.py", line 149, in get_response
    response = self.process_exception_by_middleware(e, request)
  File "C:\Python27\lib\site-packages\django\core\handlers\base.py", line 147, in get_response
    response = wrapped_callback(request, *callback_args, **callback_kwargs)
  File "C:\Python27\lib\site-packages\django\contrib\auth\decorators.py", line 23, in _wrapped_view
    return view_func(request, *args, **kwargs)
  File "E:\share\UserCenter\UsersControl\views\permission.py", line 53, in permission_edit
    form = forms.PermissionEditForm(instance=permission)
  File "E:\share\UserCenter\UsersControl\forms.py", line 192, in __init__
    super(PermissionEditForm, self).__init__(*args, **kwargs)
  File "C:\Python27\lib\site-packages\django\forms\models.py", line 282, in __init__
    object_data = model_to_dict(instance, opts.fields, opts.exclude)
  File "C:\Python27\lib\site-packages\django\forms\models.py", line 84, in model_to_dict
    opts = instance._meta
AttributeError: 'QuerySet' object has no attribute '_meta'
ERROR django.request 2017-10-24 18:49:13 C:\Python27\lib\site-packages\django\core\handlers\base.py base:handle_uncaught_exception 284 Internal Server Error: /permission/edit/9/
Traceback (most recent call last):
  File "C:\Python27\lib\site-packages\django\core\handlers\base.py", line 149, in get_response
    response = self.process_exception_by_middleware(e, request)
  File "C:\Python27\lib\site-packages\django\core\handlers\base.py", line 147, in get_response
    response = wrapped_callback(request, *callback_args, **callback_kwargs)
  File "C:\Python27\lib\site-packages\django\contrib\auth\decorators.py", line 23, in _wrapped_view
    return view_func(request, *args, **kwargs)
  File "E:\share\UserCenter\UsersControl\views\permission.py", line 53, in permission_edit
    form = forms.PermissionEditForm(instance=permission)
  File "E:\share\UserCenter\UsersControl\forms.py", line 192, in __init__
    super(PermissionEditForm, self).__init__(*args, **kwargs)
  File "C:\Python27\lib\site-packages\django\forms\models.py", line 282, in __init__
    object_data = model_to_dict(instance, opts.fields, opts.exclude)
  File "C:\Python27\lib\site-packages\django\forms\models.py", line 84, in model_to_dict
    opts = instance._meta
AttributeError: 'QuerySet' object has no attribute '_meta'
ERROR django.request 2017-10-24 18:49:34 C:\Python27\lib\site-packages\django\core\handlers\base.py base:handle_uncaught_exception 284 Internal Server Error: /permission/edit/9/
Traceback (most recent call last):
  File "C:\Python27\lib\site-packages\django\core\handlers\base.py", line 149, in get_response
    response = self.process_exception_by_middleware(e, request)
  File "C:\Python27\lib\site-packages\django\core\handlers\base.py", line 147, in get_response
    response = wrapped_callback(request, *callback_args, **callback_kwargs)
  File "C:\Python27\lib\site-packages\django\contrib\auth\decorators.py", line 23, in _wrapped_view
    return view_func(request, *args, **kwargs)
  File "E:\share\UserCenter\UsersControl\views\permission.py", line 53, in permission_edit
    form = forms.PermissionEditForm(instance=permission)
  File "E:\share\UserCenter\UsersControl\forms.py", line 192, in __init__
    super(PermissionEditForm, self).__init__(*args, **kwargs)
  File "C:\Python27\lib\site-packages\django\forms\models.py", line 282, in __init__
    object_data = model_to_dict(instance, opts.fields, opts.exclude)
  File "C:\Python27\lib\site-packages\django\forms\models.py", line 84, in model_to_dict
    opts = instance._meta
AttributeError: 'QuerySet' object has no attribute '_meta'
ERROR django.request 2017-10-24 18:52:00 C:\Python27\lib\site-packages\django\core\handlers\base.py base:handle_uncaught_exception 284 Internal Server Error: /permission/edit/9/
Traceback (most recent call last):
  File "C:\Python27\lib\site-packages\django\core\handlers\base.py", line 149, in get_response
    response = self.process_exception_by_middleware(e, request)
  File "C:\Python27\lib\site-packages\django\core\handlers\base.py", line 147, in get_response
    response = wrapped_callback(request, *callback_args, **callback_kwargs)
  File "C:\Python27\lib\site-packages\django\contrib\auth\decorators.py", line 23, in _wrapped_view
    return view_func(request, *args, **kwargs)
  File "E:\share\UserCenter\UsersControl\views\permission.py", line 53, in permission_edit
    form = forms.PermissionEditForm(instance=permission)
  File "E:\share\UserCenter\UsersControl\forms.py", line 192, in __init__
    super(PermissionEditForm, self).__init__(*args, **kwargs)
  File "C:\Python27\lib\site-packages\django\forms\models.py", line 282, in __init__
    object_data = model_to_dict(instance, opts.fields, opts.exclude)
  File "C:\Python27\lib\site-packages\django\forms\models.py", line 84, in model_to_dict
    opts = instance._meta
AttributeError: 'QuerySet' object has no attribute '_meta'
ERROR django.request 2017-10-24 18:52:07 C:\Python27\lib\site-packages\django\core\handlers\base.py base:handle_uncaught_exception 284 Internal Server Error: /permission/edit/10/
Traceback (most recent call last):
  File "C:\Python27\lib\site-packages\django\core\handlers\base.py", line 149, in get_response
    response = self.process_exception_by_middleware(e, request)
  File "C:\Python27\lib\site-packages\django\core\handlers\base.py", line 147, in get_response
    response = wrapped_callback(request, *callback_args, **callback_kwargs)
  File "C:\Python27\lib\site-packages\django\contrib\auth\decorators.py", line 23, in _wrapped_view
    return view_func(request, *args, **kwargs)
  File "E:\share\UserCenter\UsersControl\views\permission.py", line 53, in permission_edit
    form = forms.PermissionEditForm(instance=permission)
  File "E:\share\UserCenter\UsersControl\forms.py", line 192, in __init__
    super(PermissionEditForm, self).__init__(*args, **kwargs)
  File "C:\Python27\lib\site-packages\django\forms\models.py", line 282, in __init__
    object_data = model_to_dict(instance, opts.fields, opts.exclude)
  File "C:\Python27\lib\site-packages\django\forms\models.py", line 84, in model_to_dict
    opts = instance._meta
AttributeError: 'QuerySet' object has no attribute '_meta'
ERROR django.request 2017-10-24 18:59:08 C:\Python27\lib\site-packages\django\core\handlers\base.py base:handle_uncaught_exception 284 Internal Server Error: /permission/edit/9/
Traceback (most recent call last):
  File "C:\Python27\lib\site-packages\django\core\handlers\base.py", line 149, in get_response
    response = self.process_exception_by_middleware(e, request)
  File "C:\Python27\lib\site-packages\django\core\handlers\base.py", line 147, in get_response
    response = wrapped_callback(request, *callback_args, **callback_kwargs)
  File "C:\Python27\lib\site-packages\django\contrib\auth\decorators.py", line 23, in _wrapped_view
    return view_func(request, *args, **kwargs)
  File "E:\share\UserCenter\UsersControl\views\permission.py", line 53, in permission_edit
    form = forms.PermissionEditForm(instance=permission)
  File "E:\share\UserCenter\UsersControl\forms.py", line 192, in __init__
    super(PermissionEditForm, self).__init__(*args, **kwargs)
  File "C:\Python27\lib\site-packages\django\forms\models.py", line 282, in __init__
    object_data = model_to_dict(instance, opts.fields, opts.exclude)
  File "C:\Python27\lib\site-packages\django\forms\models.py", line 84, in model_to_dict
    opts = instance._meta
AttributeError: 'QuerySet' object has no attribute '_meta'
ERROR django.request 2017-10-25 08:33:23 C:\Python27\lib\site-packages\django\core\handlers\base.py base:handle_uncaught_exception 284 Internal Server Error: /permission/edit/10/
Traceback (most recent call last):
  File "C:\Python27\lib\site-packages\django\core\handlers\base.py", line 149, in get_response
    response = self.process_exception_by_middleware(e, request)
  File "C:\Python27\lib\site-packages\django\core\handlers\base.py", line 147, in get_response
    response = wrapped_callback(request, *callback_args, **callback_kwargs)
  File "C:\Python27\lib\site-packages\django\contrib\auth\decorators.py", line 23, in _wrapped_view
    return view_func(request, *args, **kwargs)
  File "E:\share\UserCenter\UsersControl\views\permission.py", line 53, in permission_edit
    form = forms.PermissionEditForm(instance=permission)
  File "E:\share\UserCenter\UsersControl\forms.py", line 192, in __init__
    super(PermissionEditForm, self).__init__(*args, **kwargs)
  File "C:\Python27\lib\site-packages\django\forms\models.py", line 282, in __init__
    object_data = model_to_dict(instance, opts.fields, opts.exclude)
  File "C:\Python27\lib\site-packages\django\forms\models.py", line 84, in model_to_dict
    opts = instance._meta
AttributeError: 'QuerySet' object has no attribute '_meta'
WARNING django.request 2017-10-25 10:17:19 C:\Python27\lib\site-packages\django\core\handlers\base.py base:get_response 182 Not Found: /favicon.ico
ERROR django.request 2017-10-25 10:58:17 C:\Python27\lib\site-packages\django\core\handlers\base.py base:handle_uncaught_exception 284 Internal Server Error: /user/add/
Traceback (most recent call last):
  File "C:\Python27\lib\site-packages\django\core\handlers\base.py", line 149, in get_response
    response = self.process_exception_by_middleware(e, request)
  File "C:\Python27\lib\site-packages\django\core\handlers\base.py", line 147, in get_response
    response = wrapped_callback(request, *callback_args, **callback_kwargs)
  File "C:\Python27\lib\site-packages\django\contrib\auth\decorators.py", line 23, in _wrapped_view
    return view_func(request, *args, **kwargs)
  File "E:\share\UserCenter\UsersControl\views\user.py", line 64, in user_add
    p = _p().push_permissions(form)
  File "E:\share\UserCenter\UsersControl\accredit\grant.py", line 21, in push_permissions
    department = Department.objects.get(name=form.cleaned_data['department']).permission.create_url.all()
AttributeError: 'ManyRelatedManager' object has no attribute 'create_url'
ERROR django.request 2017-10-25 11:06:35 C:\Python27\lib\site-packages\django\core\handlers\base.py base:handle_uncaught_exception 284 Internal Server Error: /user/add/
Traceback (most recent call last):
  File "C:\Python27\lib\site-packages\django\core\handlers\base.py", line 149, in get_response
    response = self.process_exception_by_middleware(e, request)
  File "C:\Python27\lib\site-packages\django\core\handlers\base.py", line 147, in get_response
    response = wrapped_callback(request, *callback_args, **callback_kwargs)
  File "C:\Python27\lib\site-packages\django\contrib\auth\decorators.py", line 23, in _wrapped_view
    return view_func(request, *args, **kwargs)
  File "E:\share\UserCenter\UsersControl\views\user.py", line 64, in user_add
    p = _p().push_permissions(form)
  File "E:\share\UserCenter\UsersControl\accredit\grant.py", line 22, in push_permissions
    permission_name = list(set(form.cleaned_data['allowable'] + department))
TypeError: unsupported operand type(s) for +: 'QuerySet' and 'QuerySet'
WARNING django.request 2017-10-25 13:49:32 C:\Python27\lib\site-packages\django\core\handlers\base.py base:get_response 182 Not Found: /login/user/list/
ERROR django.request 2017-10-25 13:54:15 C:\Python27\lib\site-packages\django\core\handlers\base.py base:handle_uncaught_exception 284 Internal Server Error: /user/add/
Traceback (most recent call last):
  File "C:\Python27\lib\site-packages\django\core\handlers\base.py", line 149, in get_response
    response = self.process_exception_by_middleware(e, request)
  File "C:\Python27\lib\site-packages\django\core\handlers\base.py", line 147, in get_response
    response = wrapped_callback(request, *callback_args, **callback_kwargs)
  File "C:\Python27\lib\site-packages\django\contrib\auth\decorators.py", line 23, in _wrapped_view
    return view_func(request, *args, **kwargs)
  File "E:\share\UserCenter\UsersControl\views\user.py", line 64, in user_add
    p = _p().push_permissions(form)
  File "E:\share\UserCenter\UsersControl\accredit\grant.py", line 21, in push_permissions
    print push_url_list,json.dumps(form)
  File "C:\Python27\lib\json\__init__.py", line 244, in dumps
    return _default_encoder.encode(obj)
  File "C:\Python27\lib\json\encoder.py", line 207, in encode
    chunks = self.iterencode(o, _one_shot=True)
  File "C:\Python27\lib\json\encoder.py", line 270, in iterencode
    return _iterencode(o, 0)
  File "C:\Python27\lib\json\encoder.py", line 184, in default
    raise TypeError(repr(o) + " is not JSON serializable")
TypeError: <AddUserForm bound=True, valid=True, fields=(username;nickname;email;phone;tel;rtx_num;department;is_active;sex;allowable)> is not JSON serializable
ERROR django.request 2017-10-25 13:59:51 C:\Python27\lib\site-packages\django\core\handlers\base.py base:handle_uncaught_exception 284 Internal Server Error: /user/add/
Traceback (most recent call last):
  File "C:\Python27\lib\site-packages\django\core\handlers\base.py", line 149, in get_response
    response = self.process_exception_by_middleware(e, request)
  File "C:\Python27\lib\site-packages\django\core\handlers\base.py", line 147, in get_response
    response = wrapped_callback(request, *callback_args, **callback_kwargs)
  File "C:\Python27\lib\site-packages\django\contrib\auth\decorators.py", line 23, in _wrapped_view
    return view_func(request, *args, **kwargs)
  File "E:\share\UserCenter\UsersControl\views\user.py", line 64, in user_add
    p = _p().push_permissions(form)
  File "E:\share\UserCenter\UsersControl\accredit\grant.py", line 24, in push_permissions
    'nikename':form.cleaned_data['nikename'],
KeyError: 'nikename'
ERROR django.request 2017-10-25 14:00:28 C:\Python27\lib\site-packages\django\core\handlers\base.py base:handle_uncaught_exception 284 Internal Server Error: /user/add/
Traceback (most recent call last):
  File "C:\Python27\lib\site-packages\django\core\handlers\base.py", line 149, in get_response
    response = self.process_exception_by_middleware(e, request)
  File "C:\Python27\lib\site-packages\django\core\handlers\base.py", line 147, in get_response
    response = wrapped_callback(request, *callback_args, **callback_kwargs)
  File "C:\Python27\lib\site-packages\django\contrib\auth\decorators.py", line 23, in _wrapped_view
    return view_func(request, *args, **kwargs)
  File "E:\share\UserCenter\UsersControl\views\user.py", line 64, in user_add
    p = _p().push_permissions(form)
  File "E:\share\UserCenter\UsersControl\accredit\grant.py", line 28, in push_permissions
    print push_url_list,json.dumps(data)
  File "C:\Python27\lib\json\__init__.py", line 244, in dumps
    return _default_encoder.encode(obj)
  File "C:\Python27\lib\json\encoder.py", line 207, in encode
    chunks = self.iterencode(o, _one_shot=True)
  File "C:\Python27\lib\json\encoder.py", line 270, in iterencode
    return _iterencode(o, 0)
  File "C:\Python27\lib\json\encoder.py", line 184, in default
    raise TypeError(repr(o) + " is not JSON serializable")
TypeError: <Department: 电子事业部> is not JSON serializable
ERROR django.request 2017-10-25 14:06:59 C:\Python27\lib\site-packages\django\core\handlers\base.py base:handle_uncaught_exception 284 Internal Server Error: /user/add/
Traceback (most recent call last):
  File "C:\Python27\lib\site-packages\django\core\handlers\base.py", line 149, in get_response
    response = self.process_exception_by_middleware(e, request)
  File "C:\Python27\lib\site-packages\django\core\handlers\base.py", line 147, in get_response
    response = wrapped_callback(request, *callback_args, **callback_kwargs)
  File "C:\Python27\lib\site-packages\django\contrib\auth\decorators.py", line 23, in _wrapped_view
    return view_func(request, *args, **kwargs)
  File "E:\share\UserCenter\UsersControl\views\user.py", line 64, in user_add
    p = _p().push_permissions(form)
  File "E:\share\UserCenter\UsersControl\accredit\grant.py", line 29, in push_permissions
    requests.post(i,data=data)
  File "C:\Python27\lib\site-packages\requests\api.py", line 112, in post
    return request('post', url, data=data, json=json, **kwargs)
  File "C:\Python27\lib\site-packages\requests\api.py", line 58, in request
    return session.request(method=method, url=url, **kwargs)
  File "C:\Python27\lib\site-packages\requests\sessions.py", line 513, in request
    resp = self.send(prep, **send_kwargs)
  File "C:\Python27\lib\site-packages\requests\sessions.py", line 623, in send
    r = adapter.send(request, **kwargs)
  File "C:\Python27\lib\site-packages\requests\adapters.py", line 504, in send
    raise ConnectionError(e, request=request)
ConnectionError: HTTPConnectionPool(host='www.egomsl.com', port=28000): Max retries exceeded with url: /api/receive_project_apply_from_oa/ (Caused by NewConnectionError('<urllib3.connection.HTTPConnection object at 0x00000000045EC5F8>: Failed to establish a new connection: [Errno 11004] getaddrinfo failed',))
ERROR django.request 2017-10-25 14:17:08 C:\Python27\lib\site-packages\django\core\handlers\base.py base:handle_uncaught_exception 284 Internal Server Error: /user/delete/21
Traceback (most recent call last):
  File "C:\Python27\lib\site-packages\django\core\handlers\base.py", line 149, in get_response
    response = self.process_exception_by_middleware(e, request)
  File "C:\Python27\lib\site-packages\django\core\handlers\base.py", line 147, in get_response
    response = wrapped_callback(request, *callback_args, **callback_kwargs)
  File "E:\share\UserCenter\UsersControl\views\user.py", line 104, in user_delete
    _p().revoke_permissions(user_obj)
  File "E:\share\UserCenter\UsersControl\accredit\grant.py", line 41, in revoke_permissions
    revoke_url_list = self._search_permissions(user_obj, 'revoke')
  File "E:\share\UserCenter\UsersControl\accredit\grant.py", line 58, in _search_permissions
    username=form.username).department).permission.all()]
  File "C:\Python27\lib\site-packages\django\db\models\manager.py", line 122, in manager_method
    return getattr(self.get_queryset(), name)(*args, **kwargs)
  File "C:\Python27\lib\site-packages\django\db\models\query.py", line 387, in get
    self.model._meta.object_name
DoesNotExist: UserProfile matching query does not exist.
ERROR django.request 2017-10-25 14:19:49 C:\Python27\lib\site-packages\django\core\handlers\base.py base:handle_uncaught_exception 284 Internal Server Error: /user/delete/19
Traceback (most recent call last):
  File "C:\Python27\lib\site-packages\django\core\handlers\base.py", line 149, in get_response
    response = self.process_exception_by_middleware(e, request)
  File "C:\Python27\lib\site-packages\django\core\handlers\base.py", line 147, in get_response
    response = wrapped_callback(request, *callback_args, **callback_kwargs)
  File "E:\share\UserCenter\UsersControl\views\user.py", line 104, in user_delete
    _p().revoke_permissions(user_obj)
  File "E:\share\UserCenter\UsersControl\accredit\grant.py", line 41, in revoke_permissions
    revoke_url_list = self._search_permissions(user_obj, 'revoke')
  File "E:\share\UserCenter\UsersControl\accredit\grant.py", line 57, in _search_permissions
    department_obj = UserProfile.objects.get(username=form.username)
  File "C:\Python27\lib\site-packages\django\db\models\manager.py", line 122, in manager_method
    return getattr(self.get_queryset(), name)(*args, **kwargs)
  File "C:\Python27\lib\site-packages\django\db\models\query.py", line 387, in get
    self.model._meta.object_name
DoesNotExist: UserProfile matching query does not exist.
ERROR django.request 2017-10-25 14:21:19 C:\Python27\lib\site-packages\django\core\handlers\base.py base:handle_uncaught_exception 284 Internal Server Error: /user/delete/16
Traceback (most recent call last):
  File "C:\Python27\lib\site-packages\django\core\handlers\base.py", line 149, in get_response
    response = self.process_exception_by_middleware(e, request)
  File "C:\Python27\lib\site-packages\django\core\handlers\base.py", line 147, in get_response
    response = wrapped_callback(request, *callback_args, **callback_kwargs)
  File "E:\share\UserCenter\UsersControl\views\user.py", line 101, in user_delete
    _p().revoke_permissions(user_obj)
  File "E:\share\UserCenter\UsersControl\accredit\grant.py", line 41, in revoke_permissions
    revoke_url_list = self._search_permissions(user_obj, 'revoke')
  File "E:\share\UserCenter\UsersControl\accredit\grant.py", line 58, in _search_permissions
    department = [i.delete_url for i in Department.objects.get(name=department_obj).permission.all()]
  File "C:\Python27\lib\site-packages\django\db\models\manager.py", line 122, in manager_method
    return getattr(self.get_queryset(), name)(*args, **kwargs)
  File "C:\Python27\lib\site-packages\django\db\models\query.py", line 387, in get
    self.model._meta.object_name
DoesNotExist: Department matching query does not exist.
ERROR django.request 2017-10-25 14:22:45 C:\Python27\lib\site-packages\django\core\handlers\base.py base:handle_uncaught_exception 284 Internal Server Error: /user/delete/9
Traceback (most recent call last):
  File "C:\Python27\lib\site-packages\django\core\handlers\base.py", line 149, in get_response
    response = self.process_exception_by_middleware(e, request)
  File "C:\Python27\lib\site-packages\django\core\handlers\base.py", line 147, in get_response
    response = wrapped_callback(request, *callback_args, **callback_kwargs)
  File "E:\share\UserCenter\UsersControl\views\user.py", line 101, in user_delete
    _p().revoke_permissions(user_obj)
  File "E:\share\UserCenter\UsersControl\accredit\grant.py", line 41, in revoke_permissions
    revoke_url_list = self._search_permissions(user_obj, 'revoke')
  File "E:\share\UserCenter\UsersControl\accredit\grant.py", line 60, in _search_permissions
    permission_name = [Permission.objects.get(name=i).delete_url for i in form.cleaned_data['allowable']]
AttributeError: 'UserProfile' object has no attribute 'cleaned_data'
ERROR django.request 2017-10-25 14:29:14 C:\Python27\lib\site-packages\django\core\handlers\base.py base:handle_uncaught_exception 284 Internal Server Error: /user/delete/6
Traceback (most recent call last):
  File "C:\Python27\lib\site-packages\django\core\handlers\base.py", line 149, in get_response
    response = self.process_exception_by_middleware(e, request)
  File "C:\Python27\lib\site-packages\django\core\handlers\base.py", line 147, in get_response
    response = wrapped_callback(request, *callback_args, **callback_kwargs)
  File "E:\share\UserCenter\UsersControl\views\user.py", line 101, in user_delete
    _p().revoke_permissions(user_obj)
  File "E:\share\UserCenter\UsersControl\accredit\grant.py", line 41, in revoke_permissions
    revoke_url_list = self._search_permissions(user_obj, 'revoke')
  File "E:\share\UserCenter\UsersControl\accredit\grant.py", line 59, in _search_permissions
    user_permission = [i.allowable for i in UserProfile.objects.get(username=form.username).all()]
AttributeError: 'UserProfile' object has no attribute 'all'
ERROR django.request 2017-10-25 14:32:19 C:\Python27\lib\site-packages\django\core\handlers\base.py base:handle_uncaught_exception 284 Internal Server Error: /user/delete/6
Traceback (most recent call last):
  File "C:\Python27\lib\site-packages\django\core\handlers\base.py", line 149, in get_response
    response = self.process_exception_by_middleware(e, request)
  File "C:\Python27\lib\site-packages\django\core\handlers\base.py", line 147, in get_response
    response = wrapped_callback(request, *callback_args, **callback_kwargs)
  File "E:\share\UserCenter\UsersControl\views\user.py", line 99, in user_delete
    status, res = executingldap.delete_ldap_user(user_obj)
  File "E:\share\UserCenter\UsersControl\views\executing_ldap.py", line 89, in delete_ldap_user
    status, res = self.ldaptools.delete_user(dn)
  File "E:\share\UserCenter\UsersControl\LDAP\LADPtool.py", line 102, in delete_user
    raise APIException(error_message)
APIException: {'matched': 'ou=People,dc=ldap,dc=gomeo2o,dc=cn', 'desc': 'No such object'}
ERROR django.request 2017-10-26 11:38:17 C:\Python27\lib\site-packages\django\core\handlers\base.py base:handle_uncaught_exception 284 Internal Server Error: /user/delete/16
Traceback (most recent call last):
  File "C:\Python27\lib\site-packages\django\core\handlers\base.py", line 149, in get_response
    response = self.process_exception_by_middleware(e, request)
  File "C:\Python27\lib\site-packages\django\core\handlers\base.py", line 147, in get_response
    response = wrapped_callback(request, *callback_args, **callback_kwargs)
  File "E:\share\UserCenter\UsersControl\views\user.py", line 100, in user_delete
    status, res = executingldap.delete_ldap_user(user_obj) #删除LDAP账户
  File "E:\share\UserCenter\UsersControl\LDAP\executing_ldap.py", line 89, in delete_ldap_user
    status, res = self.ldaptools.delete_user(dn)
  File "E:\share\UserCenter\UsersControl\LDAP\LADPtool.py", line 102, in delete_user
    raise APIException(error_message)
APIException: {'matched': 'ou=People,dc=ldap,dc=gomeo2o,dc=cn', 'desc': 'No such object'}
ERROR django.request 2017-10-26 11:38:21 C:\Python27\lib\site-packages\django\core\handlers\base.py base:handle_uncaught_exception 284 Internal Server Error: /user/delete/16
Traceback (most recent call last):
  File "C:\Python27\lib\site-packages\django\core\handlers\base.py", line 149, in get_response
    response = self.process_exception_by_middleware(e, request)
  File "C:\Python27\lib\site-packages\django\core\handlers\base.py", line 147, in get_response
    response = wrapped_callback(request, *callback_args, **callback_kwargs)
  File "E:\share\UserCenter\UsersControl\views\user.py", line 100, in user_delete
    status, res = executingldap.delete_ldap_user(user_obj) #删除LDAP账户
  File "E:\share\UserCenter\UsersControl\LDAP\executing_ldap.py", line 89, in delete_ldap_user
    status, res = self.ldaptools.delete_user(dn)
  File "E:\share\UserCenter\UsersControl\LDAP\LADPtool.py", line 102, in delete_user
    raise APIException(error_message)
APIException: {'matched': 'ou=People,dc=ldap,dc=gomeo2o,dc=cn', 'desc': 'No such object'}
ERROR django.request 2017-10-26 11:38:37 C:\Python27\lib\site-packages\django\core\handlers\base.py base:handle_uncaught_exception 284 Internal Server Error: /user/delete/9
Traceback (most recent call last):
  File "C:\Python27\lib\site-packages\django\core\handlers\base.py", line 149, in get_response
    response = self.process_exception_by_middleware(e, request)
  File "C:\Python27\lib\site-packages\django\core\handlers\base.py", line 147, in get_response
    response = wrapped_callback(request, *callback_args, **callback_kwargs)
  File "E:\share\UserCenter\UsersControl\views\user.py", line 100, in user_delete
    status, res = executingldap.delete_ldap_user(user_obj) #删除LDAP账户
  File "E:\share\UserCenter\UsersControl\LDAP\executing_ldap.py", line 89, in delete_ldap_user
    status, res = self.ldaptools.delete_user(dn)
  File "E:\share\UserCenter\UsersControl\LDAP\LADPtool.py", line 102, in delete_user
    raise APIException(error_message)
APIException: {'matched': 'ou=People,dc=ldap,dc=gomeo2o,dc=cn', 'desc': 'No such object'}
ERROR django.request 2017-10-26 11:38:48 C:\Python27\lib\site-packages\django\core\handlers\base.py base:handle_uncaught_exception 284 Internal Server Error: /user/delete/6
Traceback (most recent call last):
  File "C:\Python27\lib\site-packages\django\core\handlers\base.py", line 149, in get_response
    response = self.process_exception_by_middleware(e, request)
  File "C:\Python27\lib\site-packages\django\core\handlers\base.py", line 147, in get_response
    response = wrapped_callback(request, *callback_args, **callback_kwargs)
  File "E:\share\UserCenter\UsersControl\views\user.py", line 100, in user_delete
    status, res = executingldap.delete_ldap_user(user_obj) #删除LDAP账户
  File "E:\share\UserCenter\UsersControl\LDAP\executing_ldap.py", line 89, in delete_ldap_user
    status, res = self.ldaptools.delete_user(dn)
  File "E:\share\UserCenter\UsersControl\LDAP\LADPtool.py", line 102, in delete_user
    raise APIException(error_message)
APIException: {'matched': 'ou=People,dc=ldap,dc=gomeo2o,dc=cn', 'desc': 'No such object'}
WARNING django.request 2017-10-26 14:39:19 C:\Python27\lib\site-packages\django\core\handlers\base.py base:get_response 182 Not Found: /user/img/a2.jpg
WARNING django.request 2017-10-26 14:39:44 C:\Python27\lib\site-packages\django\core\handlers\base.py base:get_response 182 Not Found: /user/img/a2.jpg
WARNING django.request 2017-10-26 14:43:17 C:\Python27\lib\site-packages\django\core\handlers\base.py base:get_response 182 Not Found: /user/img/a2.jpg
WARNING django.request 2017-10-26 14:43:20 C:\Python27\lib\site-packages\django\core\handlers\base.py base:get_response 182 Not Found: /user/img/a2.jpg
WARNING django.request 2017-10-26 14:43:21 C:\Python27\lib\site-packages\django\core\handlers\base.py base:get_response 182 Not Found: /user/img/a2.jpg
WARNING django.request 2017-10-26 14:43:21 C:\Python27\lib\site-packages\django\core\handlers\base.py base:get_response 182 Not Found: /user/img/a2.jpg
WARNING django.request 2017-10-26 14:43:23 C:\Python27\lib\site-packages\django\core\handlers\base.py base:get_response 182 Not Found: /user/img/a2.jpg
WARNING django.request 2017-10-26 14:43:44 C:\Python27\lib\site-packages\django\core\handlers\base.py base:get_response 182 Not Found: /user/static/img/a2.jpg
WARNING django.request 2017-10-26 14:43:46 C:\Python27\lib\site-packages\django\core\handlers\base.py base:get_response 182 Not Found: /user/static/img/a2.jpg
ERROR django.request 2017-10-26 15:32:05 C:\Python27\lib\site-packages\django\core\handlers\base.py base:handle_uncaught_exception 284 Internal Server Error: /login
Traceback (most recent call last):
  File "C:\Python27\lib\site-packages\django\core\handlers\base.py", line 149, in get_response
    response = self.process_exception_by_middleware(e, request)
  File "C:\Python27\lib\site-packages\django\core\handlers\base.py", line 147, in get_response
    response = wrapped_callback(request, *callback_args, **callback_kwargs)
  File "C:\Python27\lib\site-packages\django\views\decorators\debug.py", line 76, in sensitive_post_parameters_wrapper
    return view(request, *args, **kwargs)
  File "C:\Python27\lib\site-packages\django\utils\decorators.py", line 149, in _wrapped_view
    response = view_func(request, *args, **kwargs)
  File "C:\Python27\lib\site-packages\django\views\decorators\cache.py", line 57, in _wrapped_view_func
    response = view_func(request, *args, **kwargs)
  File "E:\share\UserCenter\UsersControl\views\login.py", line 48, in user_login
    if user:
UnboundLocalError: local variable 'user' referenced before assignment
ERROR django.request 2017-10-26 15:32:20 C:\Python27\lib\site-packages\django\core\handlers\base.py base:handle_uncaught_exception 284 Internal Server Error: /login
Traceback (most recent call last):
  File "C:\Python27\lib\site-packages\django\core\handlers\base.py", line 149, in get_response
    response = self.process_exception_by_middleware(e, request)
  File "C:\Python27\lib\site-packages\django\core\handlers\base.py", line 147, in get_response
    response = wrapped_callback(request, *callback_args, **callback_kwargs)
  File "C:\Python27\lib\site-packages\django\views\decorators\debug.py", line 76, in sensitive_post_parameters_wrapper
    return view(request, *args, **kwargs)
  File "C:\Python27\lib\site-packages\django\utils\decorators.py", line 149, in _wrapped_view
    response = view_func(request, *args, **kwargs)
  File "C:\Python27\lib\site-packages\django\views\decorators\cache.py", line 57, in _wrapped_view_func
    response = view_func(request, *args, **kwargs)
  File "E:\share\UserCenter\UsersControl\views\login.py", line 48, in user_login
    if user:
UnboundLocalError: local variable 'user' referenced before assignment
ERROR django.request 2017-10-26 15:49:01 C:\Python27\lib\site-packages\django\core\handlers\base.py base:handle_uncaught_exception 284 Internal Server Error: /login
Traceback (most recent call last):
  File "C:\Python27\lib\site-packages\django\core\handlers\base.py", line 149, in get_response
    response = self.process_exception_by_middleware(e, request)
  File "C:\Python27\lib\site-packages\django\core\handlers\base.py", line 147, in get_response
    response = wrapped_callback(request, *callback_args, **callback_kwargs)
  File "C:\Python27\lib\site-packages\django\views\decorators\debug.py", line 76, in sensitive_post_parameters_wrapper
    return view(request, *args, **kwargs)
  File "C:\Python27\lib\site-packages\django\utils\decorators.py", line 149, in _wrapped_view
    response = view_func(request, *args, **kwargs)
  File "C:\Python27\lib\site-packages\django\views\decorators\cache.py", line 57, in _wrapped_view_func
    response = view_func(request, *args, **kwargs)
  File "E:\share\UserCenter\UsersControl\views\login.py", line 47, in user_login
    if user:
UnboundLocalError: local variable 'user' referenced before assignment
ERROR django.request 2017-10-26 15:50:55 C:\Python27\lib\site-packages\django\core\handlers\base.py base:handle_uncaught_exception 284 Internal Server Error: /login
Traceback (most recent call last):
  File "C:\Python27\lib\site-packages\django\core\handlers\base.py", line 149, in get_response
    response = self.process_exception_by_middleware(e, request)
  File "C:\Python27\lib\site-packages\django\core\handlers\base.py", line 147, in get_response
    response = wrapped_callback(request, *callback_args, **callback_kwargs)
  File "C:\Python27\lib\site-packages\django\views\decorators\debug.py", line 76, in sensitive_post_parameters_wrapper
    return view(request, *args, **kwargs)
  File "C:\Python27\lib\site-packages\django\utils\decorators.py", line 149, in _wrapped_view
    response = view_func(request, *args, **kwargs)
  File "C:\Python27\lib\site-packages\django\views\decorators\cache.py", line 57, in _wrapped_view_func
    response = view_func(request, *args, **kwargs)
  File "E:\share\UserCenter\UsersControl\views\login.py", line 42, in user_login
    user = authenticate(username=username, password=password)
  File "C:\Python27\lib\site-packages\django\contrib\auth\__init__.py", line 74, in authenticate
    user = backend.authenticate(**credentials)
  File "C:\Python27\lib\site-packages\django_auth_ldap\backend.py", line 172, in authenticate
    user = ldap_user.authenticate(password)
  File "C:\Python27\lib\site-packages\django_auth_ldap\backend.py", line 347, in authenticate
    self._get_or_create_user()
  File "C:\Python27\lib\site-packages\django_auth_ldap\backend.py", line 586, in _get_or_create_user
    self._user.save()
  File "C:\Python27\lib\site-packages\django\contrib\auth\base_user.py", line 74, in save
    super(AbstractBaseUser, self).save(*args, **kwargs)
  File "C:\Python27\lib\site-packages\django\db\models\base.py", line 708, in save
    force_update=force_update, update_fields=update_fields)
  File "C:\Python27\lib\site-packages\django\db\models\base.py", line 736, in save_base
    updated = self._save_table(raw, cls, force_insert, force_update, using, update_fields)
  File "C:\Python27\lib\site-packages\django\db\models\base.py", line 801, in _save_table
    forced_update)
  File "C:\Python27\lib\site-packages\django\db\models\base.py", line 851, in _do_update
    return filtered._update(values) > 0
  File "C:\Python27\lib\site-packages\django\db\models\query.py", line 645, in _update
    return query.get_compiler(self.db).execute_sql(CURSOR)
  File "C:\Python27\lib\site-packages\django\db\models\sql\compiler.py", line 1149, in execute_sql
    cursor = super(SQLUpdateCompiler, self).execute_sql(result_type)
  File "C:\Python27\lib\site-packages\django\db\models\sql\compiler.py", line 848, in execute_sql
    cursor.execute(sql, params)
  File "C:\Python27\lib\site-packages\django\db\backends\utils.py", line 79, in execute
    return super(CursorDebugWrapper, self).execute(sql, params)
  File "C:\Python27\lib\site-packages\django\db\backends\utils.py", line 64, in execute
    return self.cursor.execute(sql, params)
  File "C:\Python27\lib\site-packages\django\db\utils.py", line 95, in __exit__
    six.reraise(dj_exc_type, dj_exc_value, traceback)
  File "C:\Python27\lib\site-packages\django\db\backends\utils.py", line 64, in execute
    return self.cursor.execute(sql, params)
  File "C:\Python27\lib\site-packages\django\db\backends\mysql\base.py", line 112, in execute
    return self.cursor.execute(query, args)
  File "C:\Python27\lib\site-packages\MySQLdb\cursors.py", line 174, in execute
    self.errorhandler(self, exc, value)
  File "C:\Python27\lib\site-packages\MySQLdb\connections.py", line 36, in defaulterrorhandler
    raise errorclass, errorvalue
IntegrityError: (1062, "Duplicate entry 'wangyi@globalegrow.com' for key 'username'")
WARNING django.request 2017-10-26 16:31:36 C:\Python27\lib\site-packages\django\core\handlers\base.py base:get_response 182 Not Found: /user/profile.html
WARNING django.request 2017-10-26 16:32:25 C:\Python27\lib\site-packages\django\core\handlers\base.py base:get_response 182 Not Found: /user/profile.html
WARNING django.request 2017-10-26 16:32:28 C:\Python27\lib\site-packages\django\core\handlers\base.py base:get_response 182 Not Found: /user/profile.html
WARNING django.request 2017-10-26 16:32:35 C:\Python27\lib\site-packages\django\core\handlers\base.py base:get_response 182 Not Found: /user/profile.html
WARNING django.request 2017-10-26 20:21:53 C:\Python27\lib\site-packages\django\core\handlers\base.py base:get_response 182 Not Found: /password/
WARNING django.request 2017-10-26 20:40:46 C:\Python27\lib\site-packages\django\core\handlers\base.py base:get_response 182 Not Found: /password/
WARNING django.request 2017-10-26 20:42:41 C:\Python27\lib\site-packages\django\core\handlers\base.py base:get_response 182 Not Found: /password/
WARNING django.request 2017-10-27 10:02:26 C:\Python27\lib\site-packages\django\core\handlers\base.py base:get_response 182 Not Found: /accounts/permission/deny
WARNING django.request 2017-10-27 10:02:36 C:\Python27\lib\site-packages\django\core\handlers\base.py base:get_response 182 Not Found: /accounts/permission/deny
WARNING django.request 2017-10-27 10:13:40 C:\Python27\lib\site-packages\django\core\handlers\base.py base:get_response 182 Not Found: /accounts/permission/deny
WARNING django.request 2017-10-27 10:20:35 C:\Python27\lib\site-packages\django\core\handlers\base.py base:get_response 182 Not Found: /user/hades.html
WARNING django.request 2017-10-27 10:20:41 C:\Python27\lib\site-packages\django\core\handlers\base.py base:get_response 182 Not Found: /user/hades.html
WARNING django.request 2017-10-27 10:21:28 C:\Python27\lib\site-packages\django\core\handlers\base.py base:get_response 182 Not Found: /user/hades.html
WARNING django.request 2017-10-27 10:21:33 C:\Python27\lib\site-packages\django\core\handlers\base.py base:get_response 182 Not Found: /user/user/hades.html
ERROR django.request 2017-10-27 10:23:00 C:\Python27\lib\site-packages\django\core\handlers\base.py base:handle_uncaught_exception 284 Internal Server Error: /user/list
Traceback (most recent call last):
  File "C:\Python27\lib\site-packages\django\core\handlers\base.py", line 149, in get_response
    response = self.process_exception_by_middleware(e, request)
  File "C:\Python27\lib\site-packages\django\core\handlers\base.py", line 147, in get_response
    response = wrapped_callback(request, *callback_args, **callback_kwargs)
  File "E:\share\UserCenter\UsersControl\common\CustomViewPermissions.py", line 19, in _wrapped_view
    return render('/user/hades.html')
TypeError: render() takes at least 2 arguments (1 given)
ERROR django.request 2017-10-27 10:23:23 C:\Python27\lib\site-packages\django\core\handlers\base.py base:handle_uncaught_exception 284 Internal Server Error: /user/list
Traceback (most recent call last):
  File "C:\Python27\lib\site-packages\django\core\handlers\base.py", line 149, in get_response
    response = self.process_exception_by_middleware(e, request)
  File "C:\Python27\lib\site-packages\django\core\handlers\base.py", line 147, in get_response
    response = wrapped_callback(request, *callback_args, **callback_kwargs)
  File "E:\share\UserCenter\UsersControl\common\CustomViewPermissions.py", line 19, in _wrapped_view
    return render(request,'/user/hades.html')
  File "C:\Python27\lib\site-packages\django\shortcuts.py", line 67, in render
    template_name, context, request=request, using=using)
  File "C:\Python27\lib\site-packages\django\template\loader.py", line 96, in render_to_string
    template = get_template(template_name, using=using)
  File "C:\Python27\lib\site-packages\django\template\loader.py", line 43, in get_template
    raise TemplateDoesNotExist(template_name, chain=chain)
TemplateDoesNotExist: /user/hades.html
ERROR django.request 2017-10-27 10:25:45 C:\Python27\lib\site-packages\django\core\handlers\base.py base:handle_uncaught_exception 284 Internal Server Error: /user/list
Traceback (most recent call last):
  File "C:\Python27\lib\site-packages\django\core\handlers\base.py", line 149, in get_response
    response = self.process_exception_by_middleware(e, request)
  File "C:\Python27\lib\site-packages\django\core\handlers\base.py", line 147, in get_response
    response = wrapped_callback(request, *callback_args, **callback_kwargs)
  File "E:\share\UserCenter\UsersControl\common\CustomViewPermissions.py", line 19, in _wrapped_view
    return render_to_response('/user/hades.html')
  File "C:\Python27\lib\site-packages\django\shortcuts.py", line 39, in render_to_response
    content = loader.render_to_string(template_name, context, using=using)
  File "C:\Python27\lib\site-packages\django\template\loader.py", line 96, in render_to_string
    template = get_template(template_name, using=using)
  File "C:\Python27\lib\site-packages\django\template\loader.py", line 43, in get_template
    raise TemplateDoesNotExist(template_name, chain=chain)
TemplateDoesNotExist: /user/hades.html
ERROR django.request 2017-10-27 10:26:08 C:\Python27\lib\site-packages\django\core\handlers\base.py base:handle_uncaught_exception 284 Internal Server Error: /permission/list
Traceback (most recent call last):
  File "C:\Python27\lib\site-packages\django\core\handlers\base.py", line 149, in get_response
    response = self.process_exception_by_middleware(e, request)
  File "C:\Python27\lib\site-packages\django\core\handlers\base.py", line 147, in get_response
    response = wrapped_callback(request, *callback_args, **callback_kwargs)
  File "E:\share\UserCenter\UsersControl\common\CustomViewPermissions.py", line 19, in _wrapped_view
    return render_to_response('/user/hades.html')
  File "C:\Python27\lib\site-packages\django\shortcuts.py", line 39, in render_to_response
    content = loader.render_to_string(template_name, context, using=using)
  File "C:\Python27\lib\site-packages\django\template\loader.py", line 96, in render_to_string
    template = get_template(template_name, using=using)
  File "C:\Python27\lib\site-packages\django\template\loader.py", line 43, in get_template
    raise TemplateDoesNotExist(template_name, chain=chain)
TemplateDoesNotExist: /user/hades.html
ERROR django.request 2017-10-27 10:27:41 C:\Python27\lib\site-packages\django\core\handlers\base.py base:handle_uncaught_exception 284 Internal Server Error: /user/list
Traceback (most recent call last):
  File "C:\Python27\lib\site-packages\django\core\handlers\base.py", line 149, in get_response
    response = self.process_exception_by_middleware(e, request)
  File "C:\Python27\lib\site-packages\django\core\handlers\base.py", line 147, in get_response
    response = wrapped_callback(request, *callback_args, **callback_kwargs)
  File "E:\share\UserCenter\UsersControl\common\CustomViewPermissions.py", line 19, in _wrapped_view
    return render_to_response('/user/hades.html')
  File "C:\Python27\lib\site-packages\django\shortcuts.py", line 39, in render_to_response
    content = loader.render_to_string(template_name, context, using=using)
  File "C:\Python27\lib\site-packages\django\template\loader.py", line 96, in render_to_string
    template = get_template(template_name, using=using)
  File "C:\Python27\lib\site-packages\django\template\loader.py", line 43, in get_template
    raise TemplateDoesNotExist(template_name, chain=chain)
TemplateDoesNotExist: /user/hades.html
WARNING django.request 2017-10-27 10:28:43 C:\Python27\lib\site-packages\django\core\handlers\base.py base:get_response 182 Not Found: /user/hades.html
ERROR django.request 2017-10-27 10:30:06 C:\Python27\lib\site-packages\django\core\handlers\base.py base:handle_uncaught_exception 284 Internal Server Error: /user/list
Traceback (most recent call last):
  File "C:\Python27\lib\site-packages\django\core\handlers\base.py", line 149, in get_response
    response = self.process_exception_by_middleware(e, request)
  File "C:\Python27\lib\site-packages\django\core\handlers\base.py", line 147, in get_response
    response = wrapped_callback(request, *callback_args, **callback_kwargs)
  File "E:\share\UserCenter\UsersControl\common\CustomViewPermissions.py", line 19, in _wrapped_view
    return render(request,'/user/hades.html')
  File "C:\Python27\lib\site-packages\django\shortcuts.py", line 67, in render
    template_name, context, request=request, using=using)
  File "C:\Python27\lib\site-packages\django\template\loader.py", line 96, in render_to_string
    template = get_template(template_name, using=using)
  File "C:\Python27\lib\site-packages\django\template\loader.py", line 43, in get_template
    raise TemplateDoesNotExist(template_name, chain=chain)
TemplateDoesNotExist: /user/hades.html
ERROR django.request 2017-10-27 11:02:27 C:\Python27\lib\site-packages\django\core\handlers\base.py base:handle_uncaught_exception 284 Internal Server Error: /user/change_pw
Traceback (most recent call last):
  File "C:\Python27\lib\site-packages\django\core\handlers\base.py", line 149, in get_response
    response = self.process_exception_by_middleware(e, request)
  File "C:\Python27\lib\site-packages\django\core\handlers\base.py", line 147, in get_response
    response = wrapped_callback(request, *callback_args, **callback_kwargs)
  File "C:\Python27\lib\site-packages\django\contrib\auth\decorators.py", line 23, in _wrapped_view
    return view_func(request, *args, **kwargs)
  File "E:\share\UserCenter\UsersControl\views\user.py", line 123, in change_pwd
    if form.is_valid():
  File "C:\Python27\lib\site-packages\django\forms\forms.py", line 161, in is_valid
    return self.is_bound and not self.errors
  File "C:\Python27\lib\site-packages\django\forms\forms.py", line 153, in errors
    self.full_clean()
  File "C:\Python27\lib\site-packages\django\forms\forms.py", line 362, in full_clean
    self._clean_fields()
  File "C:\Python27\lib\site-packages\django\forms\forms.py", line 383, in _clean_fields
    value = getattr(self, 'clean_%s' % name)()
  File "E:\share\UserCenter\UsersControl\forms.py", line 44, in clean_old_password
    user = authenticate(username=self.user, password=old_password)
  File "C:\Python27\lib\site-packages\django\contrib\auth\__init__.py", line 74, in authenticate
    user = backend.authenticate(**credentials)
  File "C:\Python27\lib\site-packages\django_auth_ldap\backend.py", line 171, in authenticate
    ldap_user = _LDAPUser(self, username=username.strip())
  File "C:\Python27\lib\site-packages\django\utils\functional.py", line 205, in inner
    return func(self._wrapped, *args)
AttributeError: 'UserProfile' object has no attribute 'strip'
ERROR django.request 2017-10-27 11:04:44 C:\Python27\lib\site-packages\django\core\handlers\base.py base:handle_uncaught_exception 284 Internal Server Error: /user/change_pw
Traceback (most recent call last):
  File "C:\Python27\lib\site-packages\django\core\handlers\base.py", line 149, in get_response
    response = self.process_exception_by_middleware(e, request)
  File "C:\Python27\lib\site-packages\django\core\handlers\base.py", line 147, in get_response
    response = wrapped_callback(request, *callback_args, **callback_kwargs)
  File "C:\Python27\lib\site-packages\django\contrib\auth\decorators.py", line 23, in _wrapped_view
    return view_func(request, *args, **kwargs)
  File "E:\share\UserCenter\UsersControl\views\user.py", line 123, in change_pwd
    if form.is_valid():
  File "C:\Python27\lib\site-packages\django\forms\forms.py", line 161, in is_valid
    return self.is_bound and not self.errors
  File "C:\Python27\lib\site-packages\django\forms\forms.py", line 153, in errors
    self.full_clean()
  File "C:\Python27\lib\site-packages\django\forms\forms.py", line 362, in full_clean
    self._clean_fields()
  File "C:\Python27\lib\site-packages\django\forms\forms.py", line 383, in _clean_fields
    value = getattr(self, 'clean_%s' % name)()
  File "E:\share\UserCenter\UsersControl\forms.py", line 43, in clean_old_password
    user = authenticate(username=self.user, password=old_password)
  File "C:\Python27\lib\site-packages\django\contrib\auth\__init__.py", line 74, in authenticate
    user = backend.authenticate(**credentials)
  File "C:\Python27\lib\site-packages\django_auth_ldap\backend.py", line 171, in authenticate
    ldap_user = _LDAPUser(self, username=username.strip())
  File "C:\Python27\lib\site-packages\django\utils\functional.py", line 205, in inner
    return func(self._wrapped, *args)
AttributeError: 'UserProfile' object has no attribute 'strip'
ERROR django.request 2017-10-27 11:04:54 C:\Python27\lib\site-packages\django\core\handlers\base.py base:handle_uncaught_exception 284 Internal Server Error: /user/change_pw
Traceback (most recent call last):
  File "C:\Python27\lib\site-packages\django\core\handlers\base.py", line 149, in get_response
    response = self.process_exception_by_middleware(e, request)
  File "C:\Python27\lib\site-packages\django\core\handlers\base.py", line 147, in get_response
    response = wrapped_callback(request, *callback_args, **callback_kwargs)
  File "C:\Python27\lib\site-packages\django\contrib\auth\decorators.py", line 23, in _wrapped_view
    return view_func(request, *args, **kwargs)
  File "E:\share\UserCenter\UsersControl\views\user.py", line 123, in change_pwd
    if form.is_valid():
  File "C:\Python27\lib\site-packages\django\forms\forms.py", line 161, in is_valid
    return self.is_bound and not self.errors
  File "C:\Python27\lib\site-packages\django\forms\forms.py", line 153, in errors
    self.full_clean()
  File "C:\Python27\lib\site-packages\django\forms\forms.py", line 362, in full_clean
    self._clean_fields()
  File "C:\Python27\lib\site-packages\django\forms\forms.py", line 383, in _clean_fields
    value = getattr(self, 'clean_%s' % name)()
  File "E:\share\UserCenter\UsersControl\forms.py", line 43, in clean_old_password
    user = authenticate(username=self.user, password=old_password)
  File "C:\Python27\lib\site-packages\django\contrib\auth\__init__.py", line 74, in authenticate
    user = backend.authenticate(**credentials)
  File "C:\Python27\lib\site-packages\django_auth_ldap\backend.py", line 171, in authenticate
    ldap_user = _LDAPUser(self, username=username.strip())
  File "C:\Python27\lib\site-packages\django\utils\functional.py", line 205, in inner
    return func(self._wrapped, *args)
AttributeError: 'UserProfile' object has no attribute 'strip'
ERROR django.request 2017-10-27 11:05:23 C:\Python27\lib\site-packages\django\core\handlers\base.py base:handle_uncaught_exception 284 Internal Server Error: /user/change_pw
Traceback (most recent call last):
  File "C:\Python27\lib\site-packages\django\core\handlers\base.py", line 149, in get_response
    response = self.process_exception_by_middleware(e, request)
  File "C:\Python27\lib\site-packages\django\core\handlers\base.py", line 147, in get_response
    response = wrapped_callback(request, *callback_args, **callback_kwargs)
  File "C:\Python27\lib\site-packages\django\contrib\auth\decorators.py", line 23, in _wrapped_view
    return view_func(request, *args, **kwargs)
  File "E:\share\UserCenter\UsersControl\views\user.py", line 123, in change_pwd
    if form.is_valid():
  File "C:\Python27\lib\site-packages\django\forms\forms.py", line 161, in is_valid
    return self.is_bound and not self.errors
  File "C:\Python27\lib\site-packages\django\forms\forms.py", line 153, in errors
    self.full_clean()
  File "C:\Python27\lib\site-packages\django\forms\forms.py", line 362, in full_clean
    self._clean_fields()
  File "C:\Python27\lib\site-packages\django\forms\forms.py", line 383, in _clean_fields
    value = getattr(self, 'clean_%s' % name)()
  File "E:\share\UserCenter\UsersControl\forms.py", line 43, in clean_old_password
    user = authenticate(username=self.user, password=old_password)
  File "C:\Python27\lib\site-packages\django\contrib\auth\__init__.py", line 74, in authenticate
    user = backend.authenticate(**credentials)
  File "C:\Python27\lib\site-packages\django_auth_ldap\backend.py", line 171, in authenticate
    ldap_user = _LDAPUser(self, username=username.strip())
  File "C:\Python27\lib\site-packages\django\utils\functional.py", line 205, in inner
    return func(self._wrapped, *args)
AttributeError: 'UserProfile' object has no attribute 'strip'
ERROR django.request 2017-10-27 11:07:53 C:\Python27\lib\site-packages\django\core\handlers\base.py base:handle_uncaught_exception 284 Internal Server Error: /user/change_pw
Traceback (most recent call last):
  File "C:\Python27\lib\site-packages\django\core\handlers\base.py", line 149, in get_response
    response = self.process_exception_by_middleware(e, request)
  File "C:\Python27\lib\site-packages\django\core\handlers\base.py", line 147, in get_response
    response = wrapped_callback(request, *callback_args, **callback_kwargs)
  File "C:\Python27\lib\site-packages\django\contrib\auth\decorators.py", line 23, in _wrapped_view
    return view_func(request, *args, **kwargs)
  File "E:\share\UserCenter\UsersControl\views\user.py", line 123, in change_pwd
    if form.is_valid():
  File "C:\Python27\lib\site-packages\django\forms\forms.py", line 161, in is_valid
    return self.is_bound and not self.errors
  File "C:\Python27\lib\site-packages\django\forms\forms.py", line 153, in errors
    self.full_clean()
  File "C:\Python27\lib\site-packages\django\forms\forms.py", line 362, in full_clean
    self._clean_fields()
  File "C:\Python27\lib\site-packages\django\forms\forms.py", line 383, in _clean_fields
    value = getattr(self, 'clean_%s' % name)()
  File "E:\share\UserCenter\UsersControl\forms.py", line 43, in clean_old_password
    user = authenticate(username=self.user, password=old_password)
  File "C:\Python27\lib\site-packages\django\contrib\auth\__init__.py", line 74, in authenticate
    user = backend.authenticate(**credentials)
  File "C:\Python27\lib\site-packages\django_auth_ldap\backend.py", line 171, in authenticate
    ldap_user = _LDAPUser(self, username=username.strip())
  File "C:\Python27\lib\site-packages\django\utils\functional.py", line 205, in inner
    return func(self._wrapped, *args)
AttributeError: 'UserProfile' object has no attribute 'strip'
ERROR django.request 2017-10-27 11:08:02 C:\Python27\lib\site-packages\django\core\handlers\base.py base:handle_uncaught_exception 284 Internal Server Error: /user/change_pw
Traceback (most recent call last):
  File "C:\Python27\lib\site-packages\django\core\handlers\base.py", line 149, in get_response
    response = self.process_exception_by_middleware(e, request)
  File "C:\Python27\lib\site-packages\django\core\handlers\base.py", line 147, in get_response
    response = wrapped_callback(request, *callback_args, **callback_kwargs)
  File "C:\Python27\lib\site-packages\django\contrib\auth\decorators.py", line 23, in _wrapped_view
    return view_func(request, *args, **kwargs)
  File "E:\share\UserCenter\UsersControl\views\user.py", line 123, in change_pwd
    if form.is_valid():
  File "C:\Python27\lib\site-packages\django\forms\forms.py", line 161, in is_valid
    return self.is_bound and not self.errors
  File "C:\Python27\lib\site-packages\django\forms\forms.py", line 153, in errors
    self.full_clean()
  File "C:\Python27\lib\site-packages\django\forms\forms.py", line 362, in full_clean
    self._clean_fields()
  File "C:\Python27\lib\site-packages\django\forms\forms.py", line 383, in _clean_fields
    value = getattr(self, 'clean_%s' % name)()
  File "E:\share\UserCenter\UsersControl\forms.py", line 43, in clean_old_password
    user = authenticate(username=self.user, password=old_password)
  File "C:\Python27\lib\site-packages\django\contrib\auth\__init__.py", line 74, in authenticate
    user = backend.authenticate(**credentials)
  File "C:\Python27\lib\site-packages\django_auth_ldap\backend.py", line 171, in authenticate
    ldap_user = _LDAPUser(self, username=username.strip())
  File "C:\Python27\lib\site-packages\django\utils\functional.py", line 205, in inner
    return func(self._wrapped, *args)
AttributeError: 'UserProfile' object has no attribute 'strip'
ERROR django.request 2017-10-27 11:09:53 C:\Python27\lib\site-packages\django\core\handlers\base.py base:handle_uncaught_exception 284 Internal Server Error: /user/change_pw
Traceback (most recent call last):
  File "C:\Python27\lib\site-packages\django\core\handlers\base.py", line 149, in get_response
    response = self.process_exception_by_middleware(e, request)
  File "C:\Python27\lib\site-packages\django\core\handlers\base.py", line 147, in get_response
    response = wrapped_callback(request, *callback_args, **callback_kwargs)
  File "C:\Python27\lib\site-packages\django\contrib\auth\decorators.py", line 23, in _wrapped_view
    return view_func(request, *args, **kwargs)
  File "E:\share\UserCenter\UsersControl\views\user.py", line 123, in change_pwd
    if form.is_valid():
  File "C:\Python27\lib\site-packages\django\forms\forms.py", line 161, in is_valid
    return self.is_bound and not self.errors
  File "C:\Python27\lib\site-packages\django\forms\forms.py", line 153, in errors
    self.full_clean()
  File "C:\Python27\lib\site-packages\django\forms\forms.py", line 362, in full_clean
    self._clean_fields()
  File "C:\Python27\lib\site-packages\django\forms\forms.py", line 383, in _clean_fields
    value = getattr(self, 'clean_%s' % name)()
  File "E:\share\UserCenter\UsersControl\forms.py", line 43, in clean_old_password
    user = authenticate(username=self.user, password=old_password)
  File "C:\Python27\lib\site-packages\django\contrib\auth\__init__.py", line 74, in authenticate
    user = backend.authenticate(**credentials)
  File "C:\Python27\lib\site-packages\django_auth_ldap\backend.py", line 171, in authenticate
    ldap_user = _LDAPUser(self, username=username.strip())
  File "C:\Python27\lib\site-packages\django\utils\functional.py", line 205, in inner
    return func(self._wrapped, *args)
AttributeError: 'UserProfile' object has no attribute 'strip'
ERROR django.request 2017-10-27 11:22:55 C:\Python27\lib\site-packages\django\core\handlers\base.py base:handle_uncaught_exception 284 Internal Server Error: /user/change_pw
Traceback (most recent call last):
  File "C:\Python27\lib\site-packages\django\core\handlers\base.py", line 149, in get_response
    response = self.process_exception_by_middleware(e, request)
  File "C:\Python27\lib\site-packages\django\core\handlers\base.py", line 147, in get_response
    response = wrapped_callback(request, *callback_args, **callback_kwargs)
  File "C:\Python27\lib\site-packages\django\contrib\auth\decorators.py", line 23, in _wrapped_view
    return view_func(request, *args, **kwargs)
  File "E:\share\UserCenter\UsersControl\views\user.py", line 126, in change_pwd
    form.save()
  File "E:\share\UserCenter\UsersControl\forms.py", line 65, in save
    self.user.set_password(self.cleaned_data['new_password1'])
AttributeError: 'unicode' object has no attribute 'set_password'
ERROR django.request 2017-10-27 11:28:09 C:\Python27\lib\site-packages\django\core\handlers\base.py base:handle_uncaught_exception 284 Internal Server Error: /user/change_pw
Traceback (most recent call last):
  File "C:\Python27\lib\site-packages\django\core\handlers\base.py", line 149, in get_response
    response = self.process_exception_by_middleware(e, request)
  File "C:\Python27\lib\site-packages\django\core\handlers\base.py", line 147, in get_response
    response = wrapped_callback(request, *callback_args, **callback_kwargs)
  File "C:\Python27\lib\site-packages\django\contrib\auth\decorators.py", line 23, in _wrapped_view
    return view_func(request, *args, **kwargs)
  File "E:\share\UserCenter\UsersControl\views\user.py", line 128, in change_pwd
    if executing_ldap.reset_pwd_to_ldap(request.user.username, attr_list):
  File "E:\share\UserCenter\UsersControl\LDAP\executing_ldap.py", line 65, in reset_pwd_to_ldap
    dn = "cn=%s,ou=%s,%s" % (user.username,
AttributeError: 'unicode' object has no attribute 'username'
ERROR django.request 2017-10-27 11:33:23 C:\Python27\lib\site-packages\django\core\handlers\base.py base:handle_uncaught_exception 284 Internal Server Error: /user/change_pw
Traceback (most recent call last):
  File "C:\Python27\lib\site-packages\django\core\handlers\base.py", line 149, in get_response
    response = self.process_exception_by_middleware(e, request)
  File "C:\Python27\lib\site-packages\django\core\handlers\base.py", line 147, in get_response
    response = wrapped_callback(request, *callback_args, **callback_kwargs)
  File "C:\Python27\lib\site-packages\django\contrib\auth\decorators.py", line 23, in _wrapped_view
    return view_func(request, *args, **kwargs)
  File "E:\share\UserCenter\UsersControl\views\user.py", line 123, in change_pwd
    if form.is_valid():
  File "C:\Python27\lib\site-packages\django\forms\forms.py", line 161, in is_valid
    return self.is_bound and not self.errors
  File "C:\Python27\lib\site-packages\django\forms\forms.py", line 153, in errors
    self.full_clean()
  File "C:\Python27\lib\site-packages\django\forms\forms.py", line 362, in full_clean
    self._clean_fields()
  File "C:\Python27\lib\site-packages\django\forms\forms.py", line 383, in _clean_fields
    value = getattr(self, 'clean_%s' % name)()
  File "E:\share\UserCenter\UsersControl\forms.py", line 56, in clean_new_password2
    if password1 == self.cleaned_data["old_password"]:
KeyError: 'old_password'
ERROR django.request 2017-10-27 11:33:38 C:\Python27\lib\site-packages\django\core\handlers\base.py base:handle_uncaught_exception 284 Internal Server Error: /user/change_pw
Traceback (most recent call last):
  File "C:\Python27\lib\site-packages\django\core\handlers\base.py", line 149, in get_response
    response = self.process_exception_by_middleware(e, request)
  File "C:\Python27\lib\site-packages\django\core\handlers\base.py", line 147, in get_response
    response = wrapped_callback(request, *callback_args, **callback_kwargs)
  File "C:\Python27\lib\site-packages\django\contrib\auth\decorators.py", line 23, in _wrapped_view
    return view_func(request, *args, **kwargs)
  File "E:\share\UserCenter\UsersControl\views\user.py", line 123, in change_pwd
    if form.is_valid():
  File "C:\Python27\lib\site-packages\django\forms\forms.py", line 161, in is_valid
    return self.is_bound and not self.errors
  File "C:\Python27\lib\site-packages\django\forms\forms.py", line 153, in errors
    self.full_clean()
  File "C:\Python27\lib\site-packages\django\forms\forms.py", line 362, in full_clean
    self._clean_fields()
  File "C:\Python27\lib\site-packages\django\forms\forms.py", line 383, in _clean_fields
    value = getattr(self, 'clean_%s' % name)()
  File "E:\share\UserCenter\UsersControl\forms.py", line 56, in clean_new_password2
    if password1 == self.cleaned_data["old_password"]:
KeyError: 'old_password'
ERROR django.request 2017-10-27 11:35:20 C:\Python27\lib\site-packages\django\core\handlers\base.py base:handle_uncaught_exception 284 Internal Server Error: /user/change_pw
Traceback (most recent call last):
  File "C:\Python27\lib\site-packages\django\core\handlers\base.py", line 149, in get_response
    response = self.process_exception_by_middleware(e, request)
  File "C:\Python27\lib\site-packages\django\core\handlers\base.py", line 147, in get_response
    response = wrapped_callback(request, *callback_args, **callback_kwargs)
  File "C:\Python27\lib\site-packages\django\contrib\auth\decorators.py", line 23, in _wrapped_view
    return view_func(request, *args, **kwargs)
  File "E:\share\UserCenter\UsersControl\views\user.py", line 123, in change_pwd
    if form.is_valid():
  File "C:\Python27\lib\site-packages\django\forms\forms.py", line 161, in is_valid
    return self.is_bound and not self.errors
  File "C:\Python27\lib\site-packages\django\forms\forms.py", line 153, in errors
    self.full_clean()
  File "C:\Python27\lib\site-packages\django\forms\forms.py", line 362, in full_clean
    self._clean_fields()
  File "C:\Python27\lib\site-packages\django\forms\forms.py", line 383, in _clean_fields
    value = getattr(self, 'clean_%s' % name)()
  File "E:\share\UserCenter\UsersControl\forms.py", line 44, in clean_old_password
    user = authenticate(username=self.user, password=old_password)
NameError: global name 'old_password' is not defined
ERROR django.request 2017-10-27 11:36:36 C:\Python27\lib\site-packages\django\core\handlers\base.py base:handle_uncaught_exception 284 Internal Server Error: /user/list/
Traceback (most recent call last):
  File "C:\Python27\lib\site-packages\django\core\handlers\base.py", line 149, in get_response
    response = self.process_exception_by_middleware(e, request)
  File "C:\Python27\lib\site-packages\django\core\handlers\base.py", line 147, in get_response
    response = wrapped_callback(request, *callback_args, **callback_kwargs)
  File "E:\share\UserCenter\UsersControl\common\CustomViewPermissions.py", line 17, in _wrapped_view
    iUser = UserProfile.objects.get(username=request.user)
  File "C:\Python27\lib\site-packages\django\db\models\manager.py", line 122, in manager_method
    return getattr(self.get_queryset(), name)(*args, **kwargs)
  File "C:\Python27\lib\site-packages\django\db\models\query.py", line 387, in get
    self.model._meta.object_name
DoesNotExist: UserProfile matching query does not exist.
ERROR django.request 2017-10-27 11:37:17 C:\Python27\lib\site-packages\django\core\handlers\base.py base:handle_uncaught_exception 284 Internal Server Error: /
Traceback (most recent call last):
  File "C:\Python27\lib\site-packages\django\core\handlers\base.py", line 149, in get_response
    response = self.process_exception_by_middleware(e, request)
  File "C:\Python27\lib\site-packages\django\core\handlers\base.py", line 147, in get_response
    response = wrapped_callback(request, *callback_args, **callback_kwargs)
  File "E:\share\UserCenter\UsersControl\common\CustomViewPermissions.py", line 17, in _wrapped_view
    iUser = UserProfile.objects.get(username=request.user)
  File "C:\Python27\lib\site-packages\django\db\models\manager.py", line 122, in manager_method
    return getattr(self.get_queryset(), name)(*args, **kwargs)
  File "C:\Python27\lib\site-packages\django\db\models\query.py", line 387, in get
    self.model._meta.object_name
DoesNotExist: UserProfile matching query does not exist.
ERROR django.request 2017-10-27 11:37:28 C:\Python27\lib\site-packages\django\core\handlers\base.py base:handle_uncaught_exception 284 Internal Server Error: /
Traceback (most recent call last):
  File "C:\Python27\lib\site-packages\django\core\handlers\base.py", line 149, in get_response
    response = self.process_exception_by_middleware(e, request)
  File "C:\Python27\lib\site-packages\django\core\handlers\base.py", line 147, in get_response
    response = wrapped_callback(request, *callback_args, **callback_kwargs)
  File "E:\share\UserCenter\UsersControl\common\CustomViewPermissions.py", line 17, in _wrapped_view
    iUser = UserProfile.objects.get(username=request.user)
  File "C:\Python27\lib\site-packages\django\db\models\manager.py", line 122, in manager_method
    return getattr(self.get_queryset(), name)(*args, **kwargs)
  File "C:\Python27\lib\site-packages\django\db\models\query.py", line 387, in get
    self.model._meta.object_name
DoesNotExist: UserProfile matching query does not exist.
ERROR django.request 2017-10-27 11:37:41 C:\Python27\lib\site-packages\django\core\handlers\base.py base:handle_uncaught_exception 284 Internal Server Error: /
Traceback (most recent call last):
  File "C:\Python27\lib\site-packages\django\core\handlers\base.py", line 149, in get_response
    response = self.process_exception_by_middleware(e, request)
  File "C:\Python27\lib\site-packages\django\core\handlers\base.py", line 147, in get_response
    response = wrapped_callback(request, *callback_args, **callback_kwargs)
  File "E:\share\UserCenter\UsersControl\common\CustomViewPermissions.py", line 17, in _wrapped_view
    iUser = UserProfile.objects.get(username=request.user)
  File "C:\Python27\lib\site-packages\django\db\models\manager.py", line 122, in manager_method
    return getattr(self.get_queryset(), name)(*args, **kwargs)
  File "C:\Python27\lib\site-packages\django\db\models\query.py", line 387, in get
    self.model._meta.object_name
DoesNotExist: UserProfile matching query does not exist.
ERROR django.request 2017-10-27 11:39:38 C:\Python27\lib\site-packages\django\core\handlers\base.py base:handle_uncaught_exception 284 Internal Server Error: /
Traceback (most recent call last):
  File "C:\Python27\lib\site-packages\django\core\handlers\base.py", line 149, in get_response
    response = self.process_exception_by_middleware(e, request)
  File "C:\Python27\lib\site-packages\django\core\handlers\base.py", line 147, in get_response
    response = wrapped_callback(request, *callback_args, **callback_kwargs)
  File "E:\share\UserCenter\UsersControl\common\CustomViewPermissions.py", line 17, in _wrapped_view
    iUser = UserProfile.objects.get(username=request.user)
  File "C:\Python27\lib\site-packages\django\db\models\manager.py", line 122, in manager_method
    return getattr(self.get_queryset(), name)(*args, **kwargs)
  File "C:\Python27\lib\site-packages\django\db\models\query.py", line 387, in get
    self.model._meta.object_name
DoesNotExist: UserProfile matching query does not exist.
ERROR django.request 2017-10-27 11:41:00 C:\Python27\lib\site-packages\django\core\handlers\base.py base:handle_uncaught_exception 284 Internal Server Error: /
Traceback (most recent call last):
  File "C:\Python27\lib\site-packages\django\core\handlers\base.py", line 149, in get_response
    response = self.process_exception_by_middleware(e, request)
  File "C:\Python27\lib\site-packages\django\core\handlers\base.py", line 147, in get_response
    response = wrapped_callback(request, *callback_args, **callback_kwargs)
  File "E:\share\UserCenter\UsersControl\common\CustomViewPermissions.py", line 17, in _wrapped_view
    iUser = UserProfile.objects.get(username=request.user)
  File "C:\Python27\lib\site-packages\django\db\models\manager.py", line 122, in manager_method
    return getattr(self.get_queryset(), name)(*args, **kwargs)
  File "C:\Python27\lib\site-packages\django\db\models\query.py", line 387, in get
    self.model._meta.object_name
DoesNotExist: UserProfile matching query does not exist.
ERROR django.request 2017-10-27 11:41:06 C:\Python27\lib\site-packages\django\core\handlers\base.py base:handle_uncaught_exception 284 Internal Server Error: /
Traceback (most recent call last):
  File "C:\Python27\lib\site-packages\django\core\handlers\base.py", line 149, in get_response
    response = self.process_exception_by_middleware(e, request)
  File "C:\Python27\lib\site-packages\django\core\handlers\base.py", line 147, in get_response
    response = wrapped_callback(request, *callback_args, **callback_kwargs)
  File "E:\share\UserCenter\UsersControl\common\CustomViewPermissions.py", line 17, in _wrapped_view
    iUser = UserProfile.objects.get(username=request.user)
  File "C:\Python27\lib\site-packages\django\db\models\manager.py", line 122, in manager_method
    return getattr(self.get_queryset(), name)(*args, **kwargs)
  File "C:\Python27\lib\site-packages\django\db\models\query.py", line 387, in get
    self.model._meta.object_name
DoesNotExist: UserProfile matching query does not exist.
ERROR django.request 2017-10-27 11:42:14 C:\Python27\lib\site-packages\django\core\handlers\base.py base:handle_uncaught_exception 284 Internal Server Error: /
Traceback (most recent call last):
  File "C:\Python27\lib\site-packages\django\core\handlers\base.py", line 149, in get_response
    response = self.process_exception_by_middleware(e, request)
  File "C:\Python27\lib\site-packages\django\core\handlers\base.py", line 147, in get_response
    response = wrapped_callback(request, *callback_args, **callback_kwargs)
  File "E:\share\UserCenter\UsersControl\common\CustomViewPermissions.py", line 17, in _wrapped_view
    iUser = UserProfile.objects.get(username=request.user)
  File "C:\Python27\lib\site-packages\django\db\models\manager.py", line 122, in manager_method
    return getattr(self.get_queryset(), name)(*args, **kwargs)
  File "C:\Python27\lib\site-packages\django\db\models\query.py", line 387, in get
    self.model._meta.object_name
DoesNotExist: UserProfile matching query does not exist.
ERROR django.request 2017-10-27 11:42:17 C:\Python27\lib\site-packages\django\core\handlers\base.py base:handle_uncaught_exception 284 Internal Server Error: /
Traceback (most recent call last):
  File "C:\Python27\lib\site-packages\django\core\handlers\base.py", line 149, in get_response
    response = self.process_exception_by_middleware(e, request)
  File "C:\Python27\lib\site-packages\django\core\handlers\base.py", line 147, in get_response
    response = wrapped_callback(request, *callback_args, **callback_kwargs)
  File "E:\share\UserCenter\UsersControl\common\CustomViewPermissions.py", line 17, in _wrapped_view
    iUser = UserProfile.objects.get(username=request.user)
  File "C:\Python27\lib\site-packages\django\db\models\manager.py", line 122, in manager_method
    return getattr(self.get_queryset(), name)(*args, **kwargs)
  File "C:\Python27\lib\site-packages\django\db\models\query.py", line 387, in get
    self.model._meta.object_name
DoesNotExist: UserProfile matching query does not exist.
ERROR django.request 2017-10-27 11:44:04 C:\Python27\lib\site-packages\django\core\handlers\base.py base:handle_uncaught_exception 284 Internal Server Error: /
Traceback (most recent call last):
  File "C:\Python27\lib\site-packages\django\core\handlers\base.py", line 149, in get_response
    response = self.process_exception_by_middleware(e, request)
  File "C:\Python27\lib\site-packages\django\core\handlers\base.py", line 147, in get_response
    response = wrapped_callback(request, *callback_args, **callback_kwargs)
  File "E:\share\UserCenter\UsersControl\common\CustomViewPermissions.py", line 17, in _wrapped_view
    iUser = UserProfile.objects.get(username=request.user.username)
  File "C:\Python27\lib\site-packages\django\db\models\manager.py", line 122, in manager_method
    return getattr(self.get_queryset(), name)(*args, **kwargs)
  File "C:\Python27\lib\site-packages\django\db\models\query.py", line 387, in get
    self.model._meta.object_name
DoesNotExist: UserProfile matching query does not exist.
ERROR django.request 2017-10-27 11:44:08 C:\Python27\lib\site-packages\django\core\handlers\base.py base:handle_uncaught_exception 284 Internal Server Error: /
Traceback (most recent call last):
  File "C:\Python27\lib\site-packages\django\core\handlers\base.py", line 149, in get_response
    response = self.process_exception_by_middleware(e, request)
  File "C:\Python27\lib\site-packages\django\core\handlers\base.py", line 147, in get_response
    response = wrapped_callback(request, *callback_args, **callback_kwargs)
  File "E:\share\UserCenter\UsersControl\common\CustomViewPermissions.py", line 17, in _wrapped_view
    iUser = UserProfile.objects.get(username=request.user.username)
  File "C:\Python27\lib\site-packages\django\db\models\manager.py", line 122, in manager_method
    return getattr(self.get_queryset(), name)(*args, **kwargs)
  File "C:\Python27\lib\site-packages\django\db\models\query.py", line 387, in get
    self.model._meta.object_name
DoesNotExist: UserProfile matching query does not exist.
ERROR django.request 2017-10-27 11:53:57 C:\Python27\lib\site-packages\django\core\handlers\base.py base:handle_uncaught_exception 284 Internal Server Error: /user/list
Traceback (most recent call last):
  File "C:\Python27\lib\site-packages\django\core\handlers\base.py", line 158, in get_response
    % (callback.__module__, view_name))
ValueError: The view UsersControl.views.user.user_list didn't return an HttpResponse object. It returned None instead.
ERROR django.request 2017-10-27 14:00:14 C:\Python27\lib\site-packages\django\core\handlers\base.py base:handle_uncaught_exception 284 Internal Server Error: /user/change_pw
Traceback (most recent call last):
  File "C:\Python27\lib\site-packages\django\core\handlers\base.py", line 149, in get_response
    response = self.process_exception_by_middleware(e, request)
  File "C:\Python27\lib\site-packages\django\core\handlers\base.py", line 147, in get_response
    response = wrapped_callback(request, *callback_args, **callback_kwargs)
  File "C:\Python27\lib\site-packages\django\contrib\auth\decorators.py", line 23, in _wrapped_view
    return view_func(request, *args, **kwargs)
  File "E:\share\UserCenter\UsersControl\views\user.py", line 131, in change_pwd
    form.save()
  File "E:\share\UserCenter\UsersControl\forms.py", line 65, in save
    self.user.set_password(self.cleaned_data['new_password1'])
AttributeError: 'unicode' object has no attribute 'set_password'
ERROR django.request 2017-10-27 14:11:12 C:\Python27\lib\site-packages\django\core\handlers\base.py base:handle_uncaught_exception 284 Internal Server Error: /user/change_pw
Traceback (most recent call last):
  File "C:\Python27\lib\site-packages\django\core\handlers\base.py", line 149, in get_response
    response = self.process_exception_by_middleware(e, request)
  File "C:\Python27\lib\site-packages\django\core\handlers\base.py", line 147, in get_response
    response = wrapped_callback(request, *callback_args, **callback_kwargs)
  File "C:\Python27\lib\site-packages\django\contrib\auth\decorators.py", line 23, in _wrapped_view
    return view_func(request, *args, **kwargs)
  File "E:\share\UserCenter\UsersControl\views\user.py", line 130, in change_pwd
    if executing_ldap.reset_pwd_to_ldap(request.user, attr_list):
  File "E:\share\UserCenter\UsersControl\LDAP\executing_ldap.py", line 68, in reset_pwd_to_ldap
    res = self.ldaptools.modify_user(dn, attr_list)
  File "E:\share\UserCenter\UsersControl\LDAP\LADPtool.py", line 88, in modify_user
    raise APIException(error_message)
APIException: {'matched': 'ou=People,dc=ldap,dc=gomeo2o,dc=cn', 'desc': 'No such object'}
WARNING django.request 2017-10-27 14:26:52 C:\Python27\lib\site-packages\django\middleware\csrf.py csrf:_reject 103 Forbidden (CSRF token missing or incorrect.): /user/change_pw
ERROR django.request 2017-10-28 08:42:34 C:\Python27\lib\site-packages\django\core\handlers\base.py base:handle_uncaught_exception 284 Internal Server Error: /user/add/
Traceback (most recent call last):
  File "C:\Python27\lib\site-packages\django\core\handlers\base.py", line 149, in get_response
    response = self.process_exception_by_middleware(e, request)
  File "C:\Python27\lib\site-packages\django\core\handlers\base.py", line 147, in get_response
    response = wrapped_callback(request, *callback_args, **callback_kwargs)
  File "E:\share\UserCenter\UsersControl\common\CustomViewPermissions.py", line 22, in _wrapped_view
    return view_func(request, *args, **kwargs)
  File "C:\Python27\lib\site-packages\django\contrib\auth\decorators.py", line 23, in _wrapped_view
    return view_func(request, *args, **kwargs)
  File "E:\share\UserCenter\UsersControl\views\user.py", line 63, in user_add
    executing_add_user = executing_ldap.executing_add_user_to_LDAP(form, LDAP_UID, password) #创建LDAP账户
  File "E:\share\UserCenter\UsersControl\LDAP\executing_ldap.py", line 27, in executing_add_user_to_LDAP
    add_user_result = self.ldaptools.add_user(dn, add_record)
  File "E:\share\UserCenter\UsersControl\LDAP\LADPtool.py", line 67, in add_user
    raise APIException(error_message)
APIException: {'desc': 'Already exists'}
ERROR django.request 2017-10-28 08:43:26 C:\Python27\lib\site-packages\django\core\handlers\base.py base:handle_uncaught_exception 284 Internal Server Error: /user/delete/2
Traceback (most recent call last):
  File "C:\Python27\lib\site-packages\django\core\handlers\base.py", line 149, in get_response
    response = self.process_exception_by_middleware(e, request)
  File "C:\Python27\lib\site-packages\django\core\handlers\base.py", line 147, in get_response
    response = wrapped_callback(request, *callback_args, **callback_kwargs)
  File "E:\share\UserCenter\UsersControl\common\CustomViewPermissions.py", line 22, in _wrapped_view
    return view_func(request, *args, **kwargs)
  File "C:\Python27\lib\site-packages\django\contrib\auth\decorators.py", line 23, in _wrapped_view
    return view_func(request, *args, **kwargs)
  File "E:\share\UserCenter\UsersControl\views\user.py", line 110, in user_delete
    _p().revoke_permissions(user_obj) #回收权限
  File "E:\share\UserCenter\UsersControl\accredit\grant.py", line 41, in revoke_permissions
    revoke_url_list = self._search_permissions(user_obj, 'revoke')
  File "E:\share\UserCenter\UsersControl\accredit\grant.py", line 59, in _search_permissions
    username=form.username).department).permission.all()]
  File "C:\Python27\lib\site-packages\django\db\models\manager.py", line 122, in manager_method
    return getattr(self.get_queryset(), name)(*args, **kwargs)
  File "C:\Python27\lib\site-packages\django\db\models\query.py", line 387, in get
    self.model._meta.object_name
DoesNotExist: Department matching query does not exist.
ERROR django.request 2017-10-28 08:44:02 C:\Python27\lib\site-packages\django\core\handlers\base.py base:handle_uncaught_exception 284 Internal Server Error: /user/delete/2
Traceback (most recent call last):
  File "C:\Python27\lib\site-packages\django\core\handlers\base.py", line 149, in get_response
    response = self.process_exception_by_middleware(e, request)
  File "C:\Python27\lib\site-packages\django\core\handlers\base.py", line 147, in get_response
    response = wrapped_callback(request, *callback_args, **callback_kwargs)
  File "E:\share\UserCenter\UsersControl\common\CustomViewPermissions.py", line 22, in _wrapped_view
    return view_func(request, *args, **kwargs)
  File "C:\Python27\lib\site-packages\django\contrib\auth\decorators.py", line 23, in _wrapped_view
    return view_func(request, *args, **kwargs)
  File "E:\share\UserCenter\UsersControl\views\user.py", line 108, in user_delete
    status, res = executingldap.delete_ldap_user(user_obj) #删除LDAP账户
  File "E:\share\UserCenter\UsersControl\LDAP\executing_ldap.py", line 89, in delete_ldap_user
    status, res = self.ldaptools.delete_user(dn)
  File "E:\share\UserCenter\UsersControl\LDAP\LADPtool.py", line 102, in delete_user
    raise APIException(error_message)
APIException: {'matched': 'ou=People,dc=ldap,dc=gomeo2o,dc=cn', 'desc': 'No such object'}
ERROR django.request 2017-10-28 08:44:34 C:\Python27\lib\site-packages\django\core\handlers\base.py base:handle_uncaught_exception 284 Internal Server Error: /user/delete/2
Traceback (most recent call last):
  File "C:\Python27\lib\site-packages\django\core\handlers\base.py", line 149, in get_response
    response = self.process_exception_by_middleware(e, request)
  File "C:\Python27\lib\site-packages\django\core\handlers\base.py", line 147, in get_response
    response = wrapped_callback(request, *callback_args, **callback_kwargs)
  File "E:\share\UserCenter\UsersControl\common\CustomViewPermissions.py", line 22, in _wrapped_view
    return view_func(request, *args, **kwargs)
  File "C:\Python27\lib\site-packages\django\contrib\auth\decorators.py", line 23, in _wrapped_view
    return view_func(request, *args, **kwargs)
  File "E:\share\UserCenter\UsersControl\views\user.py", line 108, in user_delete
    status, res = executingldap.delete_ldap_user(user_obj) #删除LDAP账户
  File "E:\share\UserCenter\UsersControl\LDAP\executing_ldap.py", line 89, in delete_ldap_user
    status, res = self.ldaptools.delete_user(dn)
  File "E:\share\UserCenter\UsersControl\LDAP\LADPtool.py", line 102, in delete_user
    raise APIException(error_message)
APIException: {'matched': 'ou=People,dc=ldap,dc=gomeo2o,dc=cn', 'desc': 'No such object'}
ERROR django.request 2017-10-28 08:45:19 C:\Python27\lib\site-packages\django\core\handlers\base.py base:handle_uncaught_exception 284 Internal Server Error: /user/delete/2
Traceback (most recent call last):
  File "C:\Python27\lib\site-packages\django\core\handlers\base.py", line 149, in get_response
    response = self.process_exception_by_middleware(e, request)
  File "C:\Python27\lib\site-packages\django\core\handlers\base.py", line 147, in get_response
    response = wrapped_callback(request, *callback_args, **callback_kwargs)
  File "E:\share\UserCenter\UsersControl\common\CustomViewPermissions.py", line 22, in _wrapped_view
    return view_func(request, *args, **kwargs)
  File "C:\Python27\lib\site-packages\django\contrib\auth\decorators.py", line 23, in _wrapped_view
    return view_func(request, *args, **kwargs)
  File "E:\share\UserCenter\UsersControl\views\user.py", line 108, in user_delete
    status, res = executingldap.delete_ldap_user(user_obj) #删除LDAP账户
  File "E:\share\UserCenter\UsersControl\LDAP\executing_ldap.py", line 89, in delete_ldap_user
    status, res = self.ldaptools.delete_user(dn)
  File "E:\share\UserCenter\UsersControl\LDAP\LADPtool.py", line 102, in delete_user
    raise APIException(error_message)
APIException: {'matched': 'ou=People,dc=ldap,dc=gomeo2o,dc=cn', 'desc': 'No such object'}
ERROR django.request 2017-10-28 08:47:28 C:\Python27\lib\site-packages\django\core\handlers\base.py base:handle_uncaught_exception 284 Internal Server Error: /user/change_pw
Traceback (most recent call last):
  File "C:\Python27\lib\site-packages\django\core\handlers\base.py", line 149, in get_response
    response = self.process_exception_by_middleware(e, request)
  File "C:\Python27\lib\site-packages\django\core\handlers\base.py", line 147, in get_response
    response = wrapped_callback(request, *callback_args, **callback_kwargs)
  File "C:\Python27\lib\site-packages\django\contrib\auth\decorators.py", line 23, in _wrapped_view
    return view_func(request, *args, **kwargs)
  File "E:\share\UserCenter\UsersControl\views\user.py", line 130, in change_pwd
    if executing_ldap.reset_pwd_to_ldap(request.user, attr_list):
  File "E:\share\UserCenter\UsersControl\LDAP\executing_ldap.py", line 68, in reset_pwd_to_ldap
    res = self.ldaptools.modify_user(dn, attr_list)
  File "E:\share\UserCenter\UsersControl\LDAP\LADPtool.py", line 88, in modify_user
    raise APIException(error_message)
APIException: {'matched': 'ou=People,dc=ldap,dc=gomeo2o,dc=cn', 'desc': 'No such object'}
ERROR django.request 2017-10-28 08:49:30 C:\Python27\lib\site-packages\django\core\handlers\base.py base:handle_uncaught_exception 284 Internal Server Error: /user/change_pw
Traceback (most recent call last):
  File "C:\Python27\lib\site-packages\django\core\handlers\base.py", line 149, in get_response
    response = self.process_exception_by_middleware(e, request)
  File "C:\Python27\lib\site-packages\django\core\handlers\base.py", line 147, in get_response
    response = wrapped_callback(request, *callback_args, **callback_kwargs)
  File "C:\Python27\lib\site-packages\django\contrib\auth\decorators.py", line 23, in _wrapped_view
    return view_func(request, *args, **kwargs)
  File "E:\share\UserCenter\UsersControl\views\user.py", line 131, in change_pwd
    if executing_ldap.reset_pwd_to_ldap(request.user, attr_list):
  File "E:\share\UserCenter\UsersControl\LDAP\executing_ldap.py", line 68, in reset_pwd_to_ldap
    res = self.ldaptools.modify_user(dn, attr_list)
  File "E:\share\UserCenter\UsersControl\LDAP\LADPtool.py", line 88, in modify_user
    raise APIException(error_message)
APIException: {'matched': 'ou=People,dc=ldap,dc=gomeo2o,dc=cn', 'desc': 'No such object'}
WARNING django.request 2017-10-28 08:53:23 C:\Python27\lib\site-packages\django\core\handlers\base.py base:get_response 182 Not Found: /user/edit/
WARNING django.request 2017-10-28 09:00:28 C:\Python27\lib\site-packages\django\core\handlers\base.py base:get_response 182 Not Found: /favicon.ico
WARNING django.request 2017-10-28 09:00:30 C:\Python27\lib\site-packages\django\core\handlers\base.py base:get_response 182 Not Found: /favicon.ico
WARNING django.request 2017-10-28 09:00:49 C:\Python27\lib\site-packages\django\middleware\csrf.py csrf:_reject 103 Forbidden (CSRF token missing or incorrect.): /login
WARNING django.request 2017-10-28 09:00:58 C:\Python27\lib\site-packages\django\middleware\csrf.py csrf:_reject 103 Forbidden (CSRF token missing or incorrect.): /login
WARNING django.request 2017-10-28 09:01:00 C:\Python27\lib\site-packages\django\core\handlers\base.py base:get_response 182 Not Found: /login/user/list/
ERROR django.request 2017-10-28 09:54:03 C:\Python27\lib\site-packages\django\core\handlers\base.py base:handle_uncaught_exception 284 Internal Server Error: /user/edit/3/
Traceback (most recent call last):
  File "C:\Python27\lib\site-packages\django\core\handlers\base.py", line 149, in get_response
    response = self.process_exception_by_middleware(e, request)
  File "C:\Python27\lib\site-packages\django\core\handlers\base.py", line 147, in get_response
    response = wrapped_callback(request, *callback_args, **callback_kwargs)
  File "E:\share\UserCenter\UsersControl\common\CustomViewPermissions.py", line 22, in _wrapped_view
    return view_func(request, *args, **kwargs)
  File "C:\Python27\lib\site-packages\django\contrib\auth\decorators.py", line 23, in _wrapped_view
    return view_func(request, *args, **kwargs)
  File "E:\share\UserCenter\UsersControl\views\user.py", line 86, in user_edit
    comparison_info(form)
  File "E:\share\UserCenter\UsersControl\views\user.py", line 175, in comparison_info
    print user.username
AttributeError: 'QuerySet' object has no attribute 'username'
ERROR django.request 2017-10-28 09:59:07 C:\Python27\lib\site-packages\django\core\handlers\base.py base:handle_uncaught_exception 284 Internal Server Error: /user/edit/3/
Traceback (most recent call last):
  File "C:\Python27\lib\site-packages\django\core\handlers\base.py", line 149, in get_response
    response = self.process_exception_by_middleware(e, request)
  File "C:\Python27\lib\site-packages\django\core\handlers\base.py", line 147, in get_response
    response = wrapped_callback(request, *callback_args, **callback_kwargs)
  File "E:\share\UserCenter\UsersControl\common\CustomViewPermissions.py", line 22, in _wrapped_view
    return view_func(request, *args, **kwargs)
  File "C:\Python27\lib\site-packages\django\contrib\auth\decorators.py", line 23, in _wrapped_view
    return view_func(request, *args, **kwargs)
  File "E:\share\UserCenter\UsersControl\views\user.py", line 86, in user_edit
    comparison_info(form)
  File "E:\share\UserCenter\UsersControl\views\user.py", line 174, in comparison_info
    user = UserProfile.objects.filter(username=form.cleaned_data['username'])[0]
  File "C:\Python27\lib\site-packages\django\db\models\query.py", line 297, in __getitem__
    return list(qs)[0]
IndexError: list index out of range
ERROR django.request 2017-10-28 10:09:34 C:\Python27\lib\site-packages\django\core\handlers\base.py base:handle_uncaught_exception 284 Internal Server Error: /user/edit/3/
Traceback (most recent call last):
  File "C:\Python27\lib\site-packages\django\core\handlers\base.py", line 149, in get_response
    response = self.process_exception_by_middleware(e, request)
  File "C:\Python27\lib\site-packages\django\core\handlers\base.py", line 147, in get_response
    response = wrapped_callback(request, *callback_args, **callback_kwargs)
  File "E:\share\UserCenter\UsersControl\common\CustomViewPermissions.py", line 22, in _wrapped_view
    return view_func(request, *args, **kwargs)
  File "C:\Python27\lib\site-packages\django\contrib\auth\decorators.py", line 23, in _wrapped_view
    return view_func(request, *args, **kwargs)
  File "E:\share\UserCenter\UsersControl\views\user.py", line 86, in user_edit
    if comparison_info(user, form):
  File "E:\share\UserCenter\UsersControl\views\user.py", line 176, in comparison_info
    (ldap.MOD_REPLACE, 'mail', str(form.cleaned_data['mail'])),
KeyError: 'mail'
ERROR django.request 2017-10-28 10:26:05 C:\Python27\lib\site-packages\django\core\handlers\base.py base:handle_uncaught_exception 284 Internal Server Error: /user/edit/1/
Traceback (most recent call last):
  File "C:\Python27\lib\site-packages\django\core\handlers\base.py", line 149, in get_response
    response = self.process_exception_by_middleware(e, request)
  File "C:\Python27\lib\site-packages\django\core\handlers\base.py", line 147, in get_response
    response = wrapped_callback(request, *callback_args, **callback_kwargs)
  File "E:\share\UserCenter\UsersControl\common\CustomViewPermissions.py", line 22, in _wrapped_view
    return view_func(request, *args, **kwargs)
  File "C:\Python27\lib\site-packages\django\contrib\auth\decorators.py", line 23, in _wrapped_view
    return view_func(request, *args, **kwargs)
  File "E:\share\UserCenter\UsersControl\views\user.py", line 88, in user_edit
    if user.usernam != 'admin':
AttributeError: 'UserProfile' object has no attribute 'usernam'
ERROR django.request 2017-10-28 13:58:09 C:\Python27\lib\site-packages\django\core\handlers\base.py base:handle_uncaught_exception 284 Internal Server Error: /user/delete/3
Traceback (most recent call last):
  File "C:\Python27\lib\site-packages\django\core\handlers\base.py", line 149, in get_response
    response = self.process_exception_by_middleware(e, request)
  File "C:\Python27\lib\site-packages\django\core\handlers\base.py", line 147, in get_response
    response = wrapped_callback(request, *callback_args, **callback_kwargs)
  File "E:\share\UserCenter\UsersControl\common\CustomViewPermissions.py", line 17, in _wrapped_view
    iUser = UserProfile.objects.get(username=request.user)
  File "C:\Python27\lib\site-packages\django\db\models\manager.py", line 122, in manager_method
    return getattr(self.get_queryset(), name)(*args, **kwargs)
  File "C:\Python27\lib\site-packages\django\db\models\query.py", line 387, in get
    self.model._meta.object_name
DoesNotExist: UserProfile matching query does not exist.
WARNING django.request 2017-10-28 14:05:23 /usr/local/lib/python2.7/site-packages/django/core/handlers/base.py base:get_response 182 Not Found: /favicon.ico
WARNING django.request 2017-10-28 14:08:48 /usr/local/lib/python2.7/site-packages/django/core/handlers/base.py base:get_response 182 Not Found: /favicon.ico
WARNING django.request 2017-10-28 14:09:05 /usr/local/lib/python2.7/site-packages/django/middleware/csrf.py csrf:_reject 103 Forbidden (CSRF token missing or incorrect.): /login
WARNING django.request 2017-10-28 14:09:07 /usr/local/lib/python2.7/site-packages/django/core/handlers/base.py base:get_response 182 Not Found: /login/user/list/
WARNING django.request 2017-10-28 14:09:11 /usr/local/lib/python2.7/site-packages/django/core/handlers/base.py base:get_response 182 Not Found: /login/user/list/
ERROR django.request 2017-10-30 10:50:11 /usr/local/lib/python2.7/site-packages/django/core/handlers/base.py base:handle_uncaught_exception 284 Internal Server Error: /user/add
Traceback (most recent call last):
  File "/usr/local/lib/python2.7/site-packages/django/core/handlers/base.py", line 149, in get_response
    response = self.process_exception_by_middleware(e, request)
  File "/usr/local/lib/python2.7/site-packages/django/core/handlers/base.py", line 147, in get_response
    response = wrapped_callback(request, *callback_args, **callback_kwargs)
  File "/data/UserCenter/UsersControl/common/CustomViewPermissions.py", line 17, in _wrapped_view
    iUser = UserProfile.objects.get(username=request.user)
  File "/usr/local/lib/python2.7/site-packages/django/db/models/manager.py", line 122, in manager_method
    return getattr(self.get_queryset(), name)(*args, **kwargs)
  File "/usr/local/lib/python2.7/site-packages/django/db/models/query.py", line 387, in get
    self.model._meta.object_name
DoesNotExist: UserProfile matching query does not exist.
WARNING django.request 2017-11-07 18:29:21 /usr/local/lib/python2.7/site-packages/django/core/handlers/base.py base:get_response 182 Not Found: /favicon.ico
WARNING django.request 2017-11-07 18:43:50 /usr/local/lib/python2.7/site-packages/django/core/handlers/base.py base:get_response 182 Not Found: /favicon.ico
WARNING django.request 2017-11-07 18:44:10 /usr/local/lib/python2.7/site-packages/django/core/handlers/base.py base:get_response 182 Not Found: /favicon.ico
WARNING django.request 2017-11-10 11:30:06 /usr/local/lib/python2.7/site-packages/django/core/handlers/base.py base:get_response 182 Not Found: /favicon.ico
WARNING django.request 2017-11-10 11:30:08 /usr/local/lib/python2.7/site-packages/django/middleware/csrf.py csrf:_reject 103 Forbidden (CSRF token missing or incorrect.): /login
WARNING django.request 2017-11-10 11:30:11 /usr/local/lib/python2.7/site-packages/django/core/handlers/base.py base:get_response 182 Not Found: /favicon.ico
WARNING django.request 2017-11-10 11:38:20 /usr/local/lib/python2.7/site-packages/django/core/handlers/base.py base:get_response 182 Not Found: /favicon.ico
WARNING django.request 2017-11-10 11:38:27 /usr/local/lib/python2.7/site-packages/django/middleware/csrf.py csrf:_reject 103 Forbidden (CSRF token missing or incorrect.): /login
WARNING django.request 2017-11-10 11:39:51 /usr/local/lib/python2.7/site-packages/django/core/handlers/base.py base:get_response 182 Not Found: /favicon.ico
WARNING django.request 2017-11-10 11:49:27 /usr/local/lib/python2.7/site-packages/django/core/handlers/base.py base:get_response 182 Not Found: /favicon.ico
